Workbook
Name _: #REF!
Name _: #REF!
Name _: #REF!
Name _: #REF!
Name _: #REF!
Name _?: #REF!
Name _?: #REF!
Name _?: #REF!
Name _?: #REF!
Name _?: #REF!
Name _??????: #REF!
Name _??????: #REF!
Name _??????: #REF!
Name _??????: #REF!
Name _??????: #REF!
Name _2_?: #REF!
Name _2_?: #REF!
Name _2_?: #REF!
Name _2_?: #REF!
Name _2_?: #REF!
Name _3_?: #REF!
Name _3_?: #REF!
Name _3_?: #REF!
Name _3_?: #REF!
Name _3_?: #REF!
Name _4_??????: #REF!
Name _4_??????: #REF!
Name _4_??????: #REF!
Name _4_??????: #REF!
Name _4_??????: #REF!
Name _6_??????: #REF!
Name _6_??????: #REF!
Name _6_??????: #REF!
Name _6_??????: #REF!
Name _6_??????: #REF!
Name _8_8: EVALUATE+#REF!
Name _8_8: EVALUATE+#REF!
Name _8_8: EVALUATE+#REF!
Name _8_8: EVALUATE+#REF!
Name _8_8: EVALUATE+#REF!
Name _8_9: EVALUATE+#REF!
Name _8_9: EVALUATE+#REF!
Name _8_9: EVALUATE+#REF!
Name _8_9: EVALUATE+#REF!
Name _8_9: EVALUATE+#REF!
Name _999年12月31日股份应收帐款.dbf: #REF!
Name _999年12月31日股份应收帐款.dbf: #REF!
Name _999年12月31日股份应收帐款.dbf: #REF!
Name _999年12月31日股份应收帐款.dbf: #REF!
Name _999年12月31日股份应收帐款.dbf: #REF!
Name _aaa1: #REF!
Name _aaa1: #REF!
Name _aaa1: #REF!
Name _aaa1: #REF!
Name _aaa1: #REF!
Name _aaa2: #REF!
Name _aaa2: #REF!
Name _aaa2: #REF!
Name _aaa2: #REF!
Name _aaa2: #REF!

Sheet 目录
A1: 长沙五江项目-测算分析
A2: 编号 | B2: 名称
A3: 0 | B3: 基本假设与结果输出
A4: 1 | B4: 项目总投资估算表（汇总）
A5: 1.1 | B5: 项目总投资估算表（明细）
A6: 2 | B6: 投资计划与资金筹措平衡表
A7: 3 | B7: 营业收入汇总表
A8: 3.1 | B8: 销售分析
A9: 4 | B9: 增值税金及附加表
A10: 5 | B10: 运营成本汇总表
A11: 5.1 | B11: 运营成本明细表
A12: 6 | B12: 资产折旧摊销表
A13: 7 | B13: 贷款还本付息表
A14: 8 | B14: 总成本估算表
... A22: 16 | B22: 五江现金流量表（劣后级）

Sheet 0基本假设 
J1: 财务基本参数指标 | P1: 财务基本结果指标
J2: 财务基本假设/参数 | P2: 财务指标结果/评价
J3: 编号 | K3: 内容 | L3: 金额 | M3: 单位 | N3: 备注 | P3: 编号 | Q3: 内容 | R3: 金额 | S3: 单位 | T3: 备注
J4: 1 | K4: 项目总投资 | L4: ='附表1 总投资估算表（汇总)'!F20 -> 106762.97 | M4: 万元 | P4: 1 | Q4: 全投资回报指标（股权债权所有者）
J5: 1.1 | K5: 总投资估算（建安未下浮） | L5: ='附表1 总投资估算表（汇总)'!F20 -> 106762.97 | M5: 万元 | P5: 1.1 | Q5: 项目全投资所得税前收益率 | R5: ='附表12 项目全投资现金流量表'!D19 -> 0.019221046
J6: 1.2 | K6: 总投资估算（建安下浮后） | L6: - | M6: 万元 | P6: 1.2 | Q6: 项目全投资所得税后收益率 | R6: ='附表12 项目全投资现金流量表'!D20 -> 0.018534589
J7: 2 | K7: 工程费用 | L7: =L8 -> 40597.55 | M7: 万元 | N7: ="工程占比"&ROUND(L7/L4,2) -> 工程占比0.38 | P7: 1.3 | Q7: 项目全投资回收期（所得税前） | R7: ='附表12 项目全投资现金流量表'!F19 -> 4.96035 | S7: 年
J8: 2.1 | K8: 工程费用（未下浮） | L8: ='附表1 总投资估算表（汇总)'!F4 -> 40597.55 | M8: 万元 | P8: 1.4 | Q8: 项目全投资回收期（所得税后） | R8: ='附表12 项目全投资现金流量表'!F20 -> 4.9616006 | S8: 年
J9: 2.2 | K9: 工程下浮率 | L9: 0
J10: 2.3 | K10: 工程费用（建安下浮后） | L10: =L8*(1-L9) -> 40597.55 | M10: 万元 | P10: 2 | Q10: 资本金回报指标（股权投资者）
J11: 3.1 | K11: 资本金比例 | L11: =L12/L4 -> 0.59051769 | P11: 2.1 | Q11: 项目自有资金所得税前收益率 | R11: ='附表13 项目资本金现金流量'!D22 -> -0.036756886
J12: 3.2 | K12: 资本金金额 | L12: ='附表2 投资计划与资金筹措平衡表 '!O12 -> 63045.425 | M12: 万元 | P12: 2.2 | Q12: 项目自有资金投资所得税后收益率 | R12: ='附表13 项目资本金现金流量'!D23 -> -0.036756886
J13: 3.2.1 | K13: 注册资本金 | L13: 1000 | M13: 万元 | N13: 注册资本金出资比例 | P13: 2.3 | Q13: 项目自有资金投资回收期（所得税前） | R13: ='附表13 项目资本金现金流量'!F22 -> 2.767796 | S13: 年
J14: 3.2.1.1 | K14: 其中：五江方-劣后级 | L14: =$L$13*N14 -> 317.23158 | M14: 万元 | N14: =W18 -> 0.31723158 | P14: 2.4 | Q14: 项目自有资金投资回收期（所得税后） | R14: ='附表13 项目资本金现金流量'!F23 -> 2.767796 | S14: 年
J15: 3.2.1.2 | K15: 其中：中信建设-优先级 | L15: =$L$13*N15 -> 317.23158 | M15: 万元 | N15: =W18 -> 0.31723158
J16: 3.2.1.3 | K16: 其中：中信金资-中间级 | L16: =$L$13*N16 -> 111.75157 | M16: 万元 | N16: =1-N14-N15-N17 -> 0.11175157 | P16: 3 | Q16: 借贷资金回报指标（债权投资者）
J17: 3.2.1.4 | K17: 其中：其他股东 | L17: =$L$13*N17 -> 253.78527 | M17: 万元 | N17: =W19 -> 0.25378527 | P17: 3.1 | Q17: 综合偿债备付率（DSCR） | R17: ='附表7 银行贷款还本付息表'!D31 -> 2.1203097 | T17: 参考，一般需大于1.1
J18: 3.2.1.5 | K18: 其中：其他股东 | L18: =$L$13*N18 -> 0 | M18: 万元 | N18: 0 | P18: 3.2 | Q18: 利息备付系数 | R18: ='附表7 银行贷款还本付息表'!D32 -> 0.15265587 | T18: 参考，一般需大于2 | W18: =20000/L12 -> 0.31723158
J19: 3.2.2 | K19: 资本公积 | L19: =L12-L13 -> 62045.425 | M19: 万元 | N19: 资本金总出资比例 | W19: =16000/L12 -> 0.25378527
J20: 3.2.2.1 | K20: 其中：五江方-劣后级 | L20: =$L$19*N14 -> 19682.768 | M20: 万元 | N20: =N14 -> 0.31723158 | P20: 4 | Q20: 中信建设回报指标（股权投资者+工程总包商）
J21: 3.2.2.2 | K21: 其中：中信建设-优先级 | L21: =$L$19*N15 -> 19682.768 | M21: 万元 | N21: =N15 -> 0.31723158 | P21: 4.1 | Q21: 总包管理费率 | R21: ='附表14 中信建设现金流量表（优先级）'!D21 -> 0.05 | T21: ='附表14 中信建设现金流量表（优先级）'!E21 -> 0
J22: 3.2.2.3 | K22: 其中：中信金资-中间级 | L22: =$L$19*N16 -> 6933.6734 | M22: 万元 | N22: =N16 -> 0.11175157 | P22: 4.2 | Q22: 总包份额比例 | R22: ='附表14 中信建设现金流量表（优先级）'!D22 -> 1 | T22: ='附表14 中信建设现金流量表（优先级）'!E22 -> 0
J23: 3.2.2.6 | K23: =K17 -> 其中：其他股东 | L23: =$L$19*N17 -> 15746.215 | M23: 万元 | N23: =N17 -> 0.25378527 | P23: 4.3 | Q23: FIRR | R23: ='附表14 中信建设现金流量表（优先级）'!D23 -> 0.22291174 | T23: ='附表14 中信建设现金流量表（优先级）'!E23 -> 可行
J24: 3.2.2.7 | K24: =K18 -> 其中：其他股东 | L24: =$L$19*N18 -> 0 | M24: 万元 | N24: =N18 -> 0 | P24: 4.4 | Q24: 投资回收期（静态） | R24: ='附表14 中信建设现金流量表（优先级）'!D24 -> 2.960404 | S24: 年 | T24: ='附表14 中信建设现金流量表（优先级）'!E24 -> 0
J25: 4 | K25: 项目贷款 | L25: =L4-L12-L29 -> 43717.55 | M25: 万元 | N25: =L25/L4 -> 0.40948231 | P25: 4.5 | Q25: 净现值（基准投资折现率） | R25: ='附表14 中信建设现金流量表（优先级）'!D25 -> 4764.7211 | T25: ='附表14 中信建设现金流量表（优先级）'!E25 -> 可行
J26: 4.1 | K26: 贷款金额 | L26: =L4-L12-L29 -> 43717.55 | M26: 万元 | P26: 4.6 | Q26: 工程净利润 | R26: ='附表14 中信建设现金流量表（优先级）'!D26 -> 1220.2577 | T26: ='附表14 中信建设现金流量表（优先级）'!E26 -> 0
J27: 4.2 | K27: 还款期限(公益类) | L27: 0 | M27: 季度 | P27: 4.7 | Q27: 投资收益 | R27: ='附表14 中信建设现金流量表（优先级）'!D27 -> 6398.6552 | T27: ='附表14 中信建设现金流量表（优先级）'!E27 -> 0
J28: 4.3 | K28: 还款期限(经营类) | L28: 10 | M28: 季度 | P28: 4.8 | Q28: 建设期累计净现金流 | R28: ='附表14 中信建设现金流量表（优先级）'!D28 -> -394.51494 | T28: ='附表14 中信建设现金流量表（优先级）'!E28 -> 建设期回收率0.98
J29: 4 | K29: 政府建设期拨款 | L29: ='附表2 投资计划与资金筹措平衡表 '!O21 -> 0 | M29: 万元
J30: 5 | K30: 合作期 | L30: 36 | M30: 季度 | P30: 5 | Q30: 经营者回报指标 | T30: 假定第三方经营者
J31: 5.1 | K31: 建设期 | L31: 10 | M31: 季度 | P31: 5.1 | Q31: 年平均利润率
J32: 5.2 | K32: 运营期 | L32: 10 | M32: 季度 | P32: 5.2 | Q32: 年平均收入 | R32: =R34+R33 -> 327.39014
J33: 6 | K33: 资金成本 | L33: - | P33: 5.3 | Q33: 年平均成本 | R33: =AVERAGE('5.1运营成本明细表'!Q3:Z3) -> 327.39014 | S33: 万元
J34: 6.1 | K34: 长期借款利率 | L34: 0.015 | M34: 季度 | P34: 5.4 | Q34: 年平均利润 | R34: =R33*R31 -> 0 | S34: 万元
J35: 6.2 | K35: 短期借款利率 | L35: 0.008 | M35: 季度 | P35: 5.5 | Q35: 经营者资金周转率=5.2/5.3 | R35: =R32/R33 -> 1
J36: 6.3 | K36: 优先级利率 | L36: 0.0375 | M36: 季度
J37: 7 | K37: 税率与汇率 | L37: - | P37: 6 | Q37: 劣后方投资回报
J38: 7.1 | K38: 增值税及附加 | L38: - | N38: 增值税 | P38: 6.1 | Q38: 自有资金内部收益率 | R38: ='附表16五江现金流量表（劣后级）'!D24 -> -0.1303485
J39: 7.1.1 | K39: 房屋销售增值税税金及附加 | L39: 0.09 | P39: 6.2 | Q39: 投资回收期 | R39: ='附表16五江现金流量表（劣后级）'!D25 -> #REF! | S39: 年
J40: 7.1.2 | K40: 其他业务营业税金及附加 | L40: 0.06 | P40: 6.3 | Q40: 出资现值（按基准收益率） | R40: ='附表16五江现金流量表（劣后级）'!D26 -> -12048.128 | S40: 万元
...

Sheet 附表1 总投资估算表（汇总)
A1: 附表1 项目总投资估算表 (单位：万元)
A2: 序号 | B2: 费用名称 | C2: 1号路段-平原105KM | D2: 清水湾项目 | E2: 3号公路-平原168KM | F2: 投资额 | G2: 估算说明
A3: 1 | B3: 建设投资 | C3: =SUM(C4:C15) -> 0 | D3: =SUM(D4:D15) -> 103549.74 | E3: =SUM(E4:E15) -> 0 | F3: =F4+F12+F15 -> 103549.74
A4: 1.1 | B4: 工程费用 | C4: ='附表1.1 总投资估算（明细）'!H6 -> 0 | D4: ='附表1.1 总投资估算（明细）'!H16 -> 40597.55 | E4: ='附表1.1 总投资估算（明细）'!H26 -> 0 | F4: ='附表1.1 总投资估算（明细）'!H4 -> 40597.55
A5: 1.1.1 | B5: 分部分项工程合价 | F5: 0
A6: 1.1.2 | B6: 其他项目合价 | F6: 0
A7: 1.1.2.1 | B7: 暂列金额 | F7: 0
A8: 1.1.2.2 | B8: 暂估价 | F8: 0
A9: 1.1.3 | B9: 总价措施项目合价 | F9: 0
A10: 1.1.4 | B10: 规费 | F10: 0
A11: 1.1.5 | B11: 税金 | F11: 0
A12: 1.2 | B12: 工程建设其他费用 | C12: ='附表1.1 总投资估算（明细）'!$H$37*'附表1 总投资估算表（汇总)'!C22 -> 0 | D12: ='附表1.1 总投资估算（明细）'!$H$37*'附表1 总投资估算表（汇总)'!D22 -> 62952.185 | E12: ='附表1.1 总投资估算（明细）'!$H$37*'附表1 总投资估算表（汇总)'!E22 -> 0 | F12: ='附表1.1 总投资估算（明细）'!H37 -> 62952.185
A13: 1.2.1 | B13: 招标文件约定前期工作费用
A14: 1.2.2 | B14: 其他工程建设其他费用（其他二类费） | F14: 0
A15: 1.3 | B15: 预备费 | C15: ='附表1.1 总投资估算（明细）'!$H$68*0 -> 0 | D15: ='附表1.1 总投资估算（明细）'!$H$68*0 -> 0 | E15: ='附表1.1 总投资估算（明细）'!$H$68*0 -> 0 | F15: ='附表1.1 总投资估算（明细）'!H68 -> 0
A16: 1.3.1 | B16: 基本预备费
A17: 1.3.2 | B17: 涨价预备费
A18: 2 | B18: 建设期利息 | C18: ='附表2 投资计划与资金筹措平衡表 '!#REF! -> #REF! | D18: ='附表1.1 总投资估算（明细）'!H69 -> 3213.2399 | E18: ='附表2 投资计划与资金筹措平衡表 '!#REF! -> #REF! | F18: ='附表1.1 总投资估算（明细）'!H69 -> 3213.2399
A19: 3 | B19: 流动资金
B20: 项目总投资 | C20: =C3+C18 -> #REF! | D20: =D3+D18 -> 106762.97 | E20: =E3+E18 -> #REF! | F20: =F3+F18+F19 -> 106762.97
B22: 工程费用占比 | C22: =C4/$F$4 -> 0 | D22: =D4/$F$4 -> 1 | E22: =E4/$F$4 -> 0 | F22: =F4/$F$4 -> 1
B23: 工程其他费用占比 | C23: =C12/$F$12 -> 0 | D23: =D12/$F$12 -> 1 | E23: =E12/$F$12 -> 0 | F23: =F12/$F$12 -> 1
B24: 预备费占比 | C24: =C15/$F$15 -> #DIV/0! | D24: =D15/$F$15 -> #DIV/0! | E24: =E15/$F$15 -> #DIV/0! | F24: =F15/$F$15 -> #DIV/0!
B25: 利息占比 | C25: =C18/$F$18 -> #REF! | D25: =D18/$F$18 -> 1 | E25: =E18/$F$18 -> #REF! | F25: =F18/$F$18 -> 1
B26: 总投占比 | C26: =C20/$F$20 -> #REF! | D26: =D20/$F$20 -> 1 | E26: =E20/$F$20 -> #REF! | F26: =F20/$F$20 -> 1
A27: 点击返回目录

Sheet 附表1.1 总投资估算（明细）
A1: 附表1.1 总投资估算表（明细）
A2: 总投资估算表(单位：万元)
A3: 序号 | B3: 指标 | C3: 单位 | F3: 总数量 | G3: 单价 | H3: 金额 | I3: 占比
A4: 一 | B4: 工程费 | H4: =H5+H36 -> 40597.55 | I4: =H4/$H$70 -> 0.3802587
A5: 1 | B5: 建安工程费 | H5: =H6+H16+H26 -> 40597.55 | I5: =H5/$H$70 -> 0.3802587
A6: 1.1 | B6: 1号路段-平原107KM | H6: =SUM(H7,H8:H13,H14:H15) -> 0 | I6: =H6/$H$70 -> 0
A7: 1.1.1 | B7: 临时工程 | F7: 1 | G7: 0 | H7: =ROUND(F7*G7,2) -> 0 | I7: =H7/$H$70 -> 0
A8: 1.1.2 | B8: 路基工程 | F8: 1 | H8: =ROUND(F8*G8,2) -> 0 | I8: =H8/$H$70 -> 0
A9: 1.1.3 | B9: 路面工程 | F9: 1 | H9: =ROUND(F9*G9,2) -> 0 | I9: =H9/$H$70 -> 0
A10: 1.1.4 | B10: 桥梁涵洞工程 | F10: 1 | H10: =ROUND(F10*G10,2) -> 0 | I10: =H10/$H$70 -> 0
A11: 1.1.5 | B11: 交叉工程 | F11: 1 | H11: =ROUND(F11*G11,2) -> 0 | I11: =H11/$H$70 -> 0
A12: 1.1.6 | B12: 隧道工程 | F12: 1 | H12: =ROUND(F12*G12,2) -> 0 | I12: =H12/$H$70 -> 0
A13: 1.1.7 | B13: 公路设施及预埋管线工程 | F13: 1 | G13: 0 | H13: =ROUND(F13*G13,2) -> 0 | I13: =H13/$H$70 -> 0
A14: 1.1.8 | B14: 绿化及环境保护工程 | F14: 1 | G14: 0 | H14: =ROUND(F14*G14,2) -> 0 | I14: =H14/$H$70 -> 0
A15: 1.1.9 | B15: 管理、养护及服务（建设期） | F15: 1 | G15: 0 | H15: =ROUND(F15*G15,2) -> 0 | I15: =H15/$H$70 -> 0
A16: 1.1 | B16: 五江项目 | H16: =SUM(H17,H18:H25) -> 40597.55 | I16: =H16/$H$70 -> 0.3802587
A17: 1.2.1 | F17: 1 | H17: =ROUND(F17*G17,2) -> 0 | I17: =H17/$H$70 -> 0
A18: 1.2.1 | B18: 住宅 | F18: =附表3营业收入汇总表!C28/10000 -> 8.694932 | G18: ='0基本假设 '!L58 -> 3300 | H18: =ROUND(F18*G18,2) -> 28693.28 | I18: =H18/$H$70 -> 0.26875684
A19: 1.2.2 | B19: 商业 | F19: =附表3营业收入汇总表!C27/10000 -> 1.617853 | G19: ='0基本假设 '!L59 -> 3600 | H19: =ROUND(F19*G19,2) -> 5824.27 | I19: =H19/$H$70 -> 0.054553276
A20: 1.2.3 | B20: 车位 | F20: =附表3营业收入汇总表!C26/10000 -> 0.0796 | G20: ='0基本假设 '!L60 -> 50000 | H20: =ROUND(F20*G20,2) -> 3980 | I20: =H20/$H$70 -> 0.037278841
A21: 1.2.4 | B21: 工程后续成本 | H21: =ROUND(F21*G21,2) -> 0 | I21: =H21/$H$70 -> 0
A22: 1.2.5 | B22: 基础设施费 | F22: 3 | G22: 700 | H22: =ROUND(F22*G22,2) -> 2100 | I22: =H22/$H$70 -> 0.01966974
A23: 1.2.7 | F23: 1 | G23: 0 | H23: =ROUND(F23*G23,2) -> 0 | I23: =H23/$H$70 -> 0
A24: 1.2.8 | F24: 1 | G24: 0 | H24: =ROUND(F24*G24,2) -> 0 | I24: =H24/$H$70 -> 0
A25: 1.2.9 | F25: 1 | G25: 0 | H25: =ROUND(F25*G25,2) -> 0 | I25: =H25/$H$70 -> 0
A26: 1.3 | B26: 3号公路-平原148KM | H26: =SUM(H27:H35) -> 0 | I26: =H26/$H$70 -> 0
A27: 1.3.1 | B27: 临时工程 | F27: 1 | H27: =ROUND(F27*G27,2) -> 0 | I27: =H27/$H$70 -> 0
A28: 1.3.2 | B28: 路基工程 | D28: 640.8 | E28: 144.4 | F28: 1 | H28: =ROUND(F28*G28,2) -> 0 | I28: =H28/$H$70 -> 0
A29: 1.3.3 | B29: 路面工程 | F29: 1 | H29: =ROUND(F29*G29,2) -> 0 | I29: =H29/$H$70 -> 0
A30: 1.3.4 | B30: 桥梁涵洞工程 | D30: 32.9 | E30: 54 | F30: 1 | H30: =ROUND(F30*G30,2) -> 0 | I30: =H30/$H$70 -> 0
A31: 1.3.5 | B31: 交叉工程 | F31: 1 | H31: =ROUND(F31*G31,2) -> 0 | I31: =H31/$H$70 -> 0
A32: 1.3.6 | B32: 隧道工程 | D32: 0 | E32: 0 | F32: 1 | H32: =ROUND(F32*G32,2) -> 0 | I32: =H32/$H$70 -> 0
A33: 1.3.7 | B33: 公路设施及预埋管线工程 | F33: 1 | G33: =SUM(D33:E33) -> 0 | H33: =ROUND(F33*G33,2) -> 0 | I33: =H33/$H$70 -> 0
A34: 1.3.8 | B34: 绿化及环境保护工程 | F34: 1 | G34: =SUM(D34:E34) -> 0 | H34: =ROUND(F34*G34,2) -> 0 | I34: =H34/$H$70 -> 0
A35: 1.3.9 | B35: 管理、养护及服务（建设期） | F35: 1 | G35: =SUM(D35:E35) -> 0 | H35: =ROUND(F35*G35,2) -> 0 | I35: =H35/$H$70 -> 0
A36: 2 | B36: 设备及工具、器具购置费 | G36: 0 | H36: =ROUND(F36*G36,2) -> 0 | I36: =H36/$H$70 -> 0
A37: 二 | B37: 工程建设其他费用 | H37: =SUM(H43,H49:H51,H55:H57,H62:H67)+H38 -> 62952.185 | I37: =H37/$H$70 -> 0.58964435
A38: 0 | B38: 土地费用 | C38: 项 | F38: 0 | H38: =SUM(H39:H42) -> 59832.185 | I38: =H38/$H$70 -> 0.56042074
A39: 0.1 | B39: 土地出让金 | F39: 52770 | G39: 1 | H39: =F39*G39 -> 52770
A40: 0.2 | B40: 契税 | F40: =F39*0.04 -> 2110.8 | G40: 1 | H40: =F40*G40 -> 2110.8
...

Sheet 附表2 投资计划与资金筹措平衡表 
B2: 附表2 投资计划与资金筹措平衡表 (单位：万元)
B3: 序号 | D3: 建设期 | O3: 合计 | P3: 占总投资比例 | R3: 投资进度
C4: 项目 | D4: 第1年Q1 | E4: 第1年Q2 | F4: 第1年Q3 | G4: 第1年Q4 | H4: 第2年Q3 | I4: 第2年Q4 | J4: 第2年Q3 | K4: 第2年Q4 | L4: 第3年Q31 | M4: 第3年Q2 | N4: 第5年 | R4: 第1年Q1 | S4: 第1年Q2 | T4: 第1年Q3 | U4: 第1年Q4 | V4: 第2年Q3 | W4: 第2年Q4 | X4: 第3年Q1 | Y4: 第3年Q2 | Z4: 第3年Q3 | AA4: 第3年Q4 | AB4: 第5年 | AC4: 合计
B5: 1 | C5: 项目总投资 | D5: =D6+D7+D8+D9 -> 59832.185 | E5: =E6+E7+E8+E9 -> 8809.0863 | F5: =F6+F7+F8+F9 -> 4535.6958 | G5: =G6+G7+G8+G9 -> 4601.2721 | H5: =H6+H7+H8+H9 -> 4666.8485 | I5: =I6+I7+I8+I9 -> 4732.4248 | J5: =J6+J7+J8+J9 -> 4798.0011 | K5: =K6+K7+K8+K9 -> 4863.5774 | ... M5: =M6+M7+M8+M9 -> 4994.7301 | O5: =SUM(D5:M5) -> 106762.97 | P5: =O5/$O$5 -> 1 | R5: =D5/$O$5 -> 0.56042074 | S5: =E5/$O$5 -> 0.082510686 | T5: =F5/$O$5 -> 0.04248379 | U5: =G5/$O$5 -> 0.043098014 | V5: =H5/$O$5 -> 0.043712237 | W5: =I5/$O$5 -> 0.04432646 | X5: =J5/$O$5 -> 0.044940684 | Y5: =K5/$O$5 -> 0.045554907 | ... AA5: =M5/$O$5 -> 0.046783354 | AC5: =SUM(R5:AA5) -> 1
B6: 1.1 | C6: 工程费用 | E6: ='附表1.1 总投资估算（明细）'!$H$4*(R12+S12) -> 8119.51 | F6: ='附表1.1 总投资估算（明细）'!$H$4*'附表2 投资计划与资金筹措平衡表 '!T$12 -> 4059.755 | G6: ='附表1.1 总投资估算（明细）'!$H$4*'附表2 投资计划与资金筹措平衡表 '!U$12 -> 4059.755 | H6: ='附表1.1 总投资估算（明细）'!$H$4*'附表2 投资计划与资金筹措平衡表 '!V$12 -> 4059.755 | I6: ='附表1.1 总投资估算（明细）'!$H$4*'附表2 投资计划与资金筹措平衡表 '!W$12 -> 4059.755 | J6: ='附表1.1 总投资估算（明细）'!$H$4*'附表2 投资计划与资金筹措平衡表 '!X$12 -> 4059.755 | K6: ='附表1.1 总投资估算（明细）'!$H$4*'附表2 投资计划与资金筹措平衡表 '!Y$12 -> 4059.755 | L6: ='附表1.1 总投资估算（明细）'!$H$4*'附表2 投资计划与资金筹措平衡表 '!Z$12 -> 4059.755 | M6: ='附表1.1 总投资估算（明细）'!$H$4*'附表2 投资计划与资金筹措平衡表 '!AA$12 -> 4059.755 | O6: =SUM(D6:M6) -> 40597.55 | P6: =O6/$O$5 -> 0.3802587 | R6: 根据工程进度及工程建设其他费进度及预备费的调整后的投资进度如上
B7: 1.2 | C7: 工程建设其他费 | D7: ='附表1.1 总投资估算（明细）'!H38 -> 59832.185 | E7: =('附表1.1 总投资估算（明细）'!$H$37-'附表1.1 总投资估算（明细）'!$H$38)*(R16+S16) -> 624 | F7: =('附表1.1 总投资估算（明细）'!$H$37-'附表1.1 总投资估算（明细）'!$H$38)*T16 -> 312 | G7: =('附表1.1 总投资估算（明细）'!$H$37-'附表1.1 总投资估算（明细）'!$H$38)*U16 -> 312 | H7: =('附表1.1 总投资估算（明细）'!$H$37-'附表1.1 总投资估算（明细）'!$H$38)*V16 -> 312 | I7: =('附表1.1 总投资估算（明细）'!$H$37-'附表1.1 总投资估算（明细）'!$H$38)*W16 -> 312 | J7: =('附表1.1 总投资估算（明细）'!$H$37-'附表1.1 总投资估算（明细）'!$H$38)*X16 -> 312 | K7: =('附表1.1 总投资估算（明细）'!$H$37-'附表1.1 总投资估算（明细）'!$H$38)*Y16 -> 312 | L7: =('附表1.1 总投资估算（明细）'!$H$37-'附表1.1 总投资估算（明细）'!$H$38)*Z16 -> 312 | M7: =('附表1.1 总投资估算（明细）'!$H$37-'附表1.1 总投资估算（明细）'!$H$38)*AA16 -> 312 | N7: ='附表1.1 总投资估算（明细）'!$H$37*AB16 -> 0 | O7: =SUM(D7:M7) -> 62952.185 | P7: =O7/$O$5 -> 0.58964435
B8: 1.3 | C8: 预备费 | D8: =D20+D25 -> 0 | E8: =E20+E25 -> 0 | F8: =F20+F25 -> 0 | G8: =G20+G25 -> 0 | H8: =H20+H25 -> 0 | I8: =I20+I25 -> 0 | J8: =J20+J25 -> 0 | K8: =K20+K25 -> 0 | ... M8: =M20+M25 -> 0 | O8: =SUM(D8:M8) -> 0 | P8: =O8/$O$5 -> 0
B9: 1.4 | C9: 建设期利息 | D9: =D15+D19+D24 -> 0 | E9: =E15+E19+E24 -> 65.576325 | F9: =F15+F19+F24 -> 163.94081 | G9: =G15+G19+G24 -> 229.51714 | H9: =H15+H19+H24 -> 295.09346 | I9: =I15+I19+I24 -> 360.66979 | J9: =J15+J19+J24 -> 426.24611 | K9: =K15+K19+K24 -> 491.82244 | ... M9: =M15+M19+M24 -> 622.97509 | O9: =SUM(D9:M9) -> 3213.2399 | P9: =O9/$O$5 -> 0.03009695 | R9: 工程进度
B10: 1.5 | C10: 流动资金 | M10: =M20 -> 0 | O10: =SUM(D10:M10) -> 0 | P10: =O10/$O$5 -> 0 | R10: 工程进度
B11: 2 | C11: 资金筹措 | D11: =D12+D16+D21 -> 59832.185 | E11: =E12+E16+E21 -> 8809.0863 | F11: =F12+F16+F21 -> 4535.6958 | G11: =G12+G16+G21 -> 4601.2721 | H11: =H12+H16+H21 -> 4666.8485 | I11: =I12+I16+I21 -> 4732.4248 | J11: =J12+J16+J21 -> 4798.0011 | K11: =K12+K16+K21 -> 4863.5774 | ... N11: =N12+N16+N21 -> 0 | O11: =SUM(D11:M11) -> 106762.97 | P11: =O11/$O$5 -> 1 | R11: 第1年Q1 | S11: 第1年Q2 | T11: 第1年Q3 | U11: 第1年Q4 | V11: 第2年Q3 | W11: 第2年Q4 | X11: 第3年Q1 | Y11: 第3年Q2 | Z11: 第3年Q3 | AA11: 第3年Q4 | AB11: 第5年 | AC11: 合计
B12: 2.1 | C12: 项目资本金 | D12: =SUM(D13:D15) -> 59832.185 | E12: =SUM(E13:E15) -> 65.576325 | F12: =SUM(F13:F15) -> 163.94081 | G12: =SUM(G13:G15) -> 229.51714 | H12: =SUM(H13:H15) -> 295.09346 | I12: =SUM(I13:I15) -> 360.66979 | J12: =SUM(J13:J15) -> 426.24611 | K12: =SUM(K13:K15) -> 491.82244 | ... N12: =SUM(N13:N15) -> 0 | O12: =SUM(D12:M12) -> 63045.425 | P12: =O12/$O$5 -> 0.59051769 | R12: 0.1 | S12: 0.1 | T12: 0.1 | U12: 0.1 | V12: 0.1 | W12: 0.1 | X12: 0.1 | Y12: 0.1 | Z12: 0.1 | AA12: 0.1 | AC12: =SUM(R12:AB12) -> 1
B13: 2.1.1 | C13: 用于工程费用 | E13: =E6-E17 -> 0 | F13: =F6-F17 -> 0 | G13: =G6-G17 -> 0 | H13: =H6-H17 -> 0 | I13: =I6-I17 -> 0 | J13: =J6-J17 -> 0 | K13: =K6-K17 -> 0 | L13: =L6-L17 -> 0 | M13: =M6-M17 -> 0 | O13: =SUM(D13:M13) -> 0 | P13: =O13/$O$5 -> 0
B14: 2.1.2 | C14: 用于工程其他费 | D14: ='附表1.1 总投资估算（明细）'!H38 -> 59832.185 | E14: =E7-E18 -> 0 | F14: =F7-F18 -> 0 | G14: =G7-G18 -> 0 | H14: =H7-H18 -> 0 | I14: =I7-I18 -> 0 | J14: =J7-J18 -> 0 | K14: =K7-K18 -> 0 | L14: =L7-L18 -> 0 | M14: =M7-M18 -> 0 | O14: =SUM(D14:M14) -> 59832.185 | P14: =O14/$O$5 -> 0.56042074 | R14: 工程建设其他费及前期费用投资进度
B15: 2.1.3 | C15: 用于建设期利息 | E15: =E29 -> 65.576325 | F15: =F29 -> 163.94081 | G15: =G29 -> 229.51714 | H15: =H29 -> 295.09346 | I15: =I29 -> 360.66979 | J15: =J29 -> 426.24611 | K15: =K29 -> 491.82244 | L15: =L29 -> 557.39876 | M15: =M29 -> 622.97509 | O15: =SUM(D15:M15) -> 3213.2399 | R15: 第1年Q1 | S15: 第1年Q2 | T15: 第1年Q3 | U15: 第1年Q4 | V15: 第2年Q3 | W15: 第2年Q4 | X15: 第3年Q1 | Y15: 第3年Q2 | Z15: 第3年Q3 | AA15: 第3年Q4 | AB15: 第5年 | AC15: 合计
B16: 2.2 | C16: 债务性资金 | D16: =D17+D18+D19+D20 -> 0 | E16: =E17+E18+E19+E20 -> 8743.51 | F16: =F17+F18+F19+F20 -> 4371.755 | G16: =G17+G18+G19+G20 -> 4371.755 | H16: =H17+H18+H19+H20 -> 4371.755 | I16: =I17+I18+I19+I20 -> 4371.755 | J16: =J17+J18+J19+J20 -> 4371.755 | K16: =K17+K18+K19+K20 -> 4371.755 | ... M16: =M17+M18+M19+M20 -> 4371.755 | O16: =SUM(D16:M16) -> 43717.55 | P16: =O16/$O$5 -> 0.40948231 | R16: =R12 -> 0.1 | S16: =S12 -> 0.1 | T16: =T12 -> 0.1 | U16: =U12 -> 0.1 | V16: =V12 -> 0.1 | W16: =W12 -> 0.1 | X16: =X12 -> 0.1 | Y16: =Y12 -> 0.1 | ... AA16: =AA12 -> 0.1 | AC16: =SUM(R16:AA16) -> 1
B17: 2.2.1 | C17: 用于工程费用 | E17: =$R$21*(S12+R12) -> 8119.51 | F17: =$R$21*T12 -> 4059.755 | G17: =$R$21*U12 -> 4059.755 | H17: =$R$21*V12 -> 4059.755 | I17: =$R$21*W12 -> 4059.755 | J17: =$R$21*X12 -> 4059.755 | K17: =$R$21*Y12 -> 4059.755 | L17: =$R$21*Z12 -> 4059.755 | M17: =$R$21*AA12 -> 4059.755 | N17: =$R$23*AB12 -> 0 | O17: =SUM(D17:M17) -> 40597.55 | P17: =O17/$O$5 -> 0.3802587 | R17: 按照项目公司未来筹集计划，土地使用费、城市建设配套费、前期工作咨询费、规划设计费、招标代理费需要第一年支付；其余工程其他费用后续支付
B18: 2.2.2 | C18: 用于工程其他费 | D18: 0 | E18: =$R$22*(S16+R16) -> 624 | F18: =$R$22*T16 -> 312 | G18: =$R$22*U16 -> 312 | H18: =$R$22*V16 -> 312 | I18: =$R$22*W16 -> 312 | J18: =$R$22*X16 -> 312 | K18: =$R$22*Y16 -> 312 | L18: =$R$22*Z16 -> 312 | M18: =$R$22*AA16 -> 312 | O18: =SUM(D18:N18) -> 3120 | P18: =O18/$O$5 -> 0.029223614
B19: 2.2.3 | C19: 用于建设期利息 | D19: 0 | E19: 0 | F19: 0 | G19: 0 | H19: 0 | I19: 0 | J19: 0 | K19: 0 | L19: 0 | M19: 0 | O19: =SUM(D19:N19) -> 0 | P19: =O19/$O$5 -> 0
B20: 2.2.4 | C20: 用于预备费 | O20: =SUM(D20:N20) -> 0 | P20: =O20/$O$5 -> 0
B21: 2.3 | C21: 政府建设拨款 | D21: =D22+D23+D24+D25 -> 0 | E21: =E22+E23+E24+E25 -> 0 | F21: =F22+F23+F24+F25 -> 0 | G21: =G22+G23+G24+G25 -> 0 | H21: =H22+H23+H24+H25 -> 0 | I21: =I22+I23+I24+I25 -> 0 | J21: =J22+J23+J24+J25 -> 0 | K21: =K22+K23+K24+K25 -> 0 | ... N21: =N22+N23+N24+N25 -> 0 | O21: =SUM(D21:N21) -> 0 | P21: =O21/$O$5 -> 0 | R21: ='附表1.1 总投资估算（明细）'!H4 -> 40597.55
B22: 2.2.1 | C22: 用于工程费用 | D22: =D6*'0基本假设 '!$N$29 -> 0 | E22: =E6*'0基本假设 '!$N$29 -> 0 | F22: =F6*'0基本假设 '!$N$29 -> 0 | G22: =G6*'0基本假设 '!$N$29 -> 0 | H22: =H6*'0基本假设 '!$N$29 -> 0 | I22: =I6*'0基本假设 '!$N$29 -> 0 | J22: =J6*'0基本假设 '!$N$29 -> 0 | K22: =K6*'0基本假设 '!$N$29 -> 0 | ... M22: =M6*'0基本假设 '!$N$29 -> 0 | O22: =SUM(D22:N22) -> 0 | P22: =O22/$O$5 -> 0 | R22: ='附表1.1 总投资估算（明细）'!H37-'附表1.1 总投资估算（明细）'!H38 -> 3120
B23: 2.2.2 | C23: 用于工程其他费 | O23: =SUM(D23:N23) -> 0 | P23: =O23/$O$5 -> 0 | R23: ='附表1.1 总投资估算（明细）'!H4+'附表1.1 总投资估算（明细）'!H43 -> 43717.55
B24: 2.2.3 | C24: 用于建设期利息 | O24: =SUM(D24:N24) -> 0 | P24: =O24/$O$5 -> 0
B25: 2.2.4 | C25: 用于预备费 | O25: =SUM(D25:N25) -> 0 | P25: =O25/$O$5 -> 0
D27: 建设期利息计算过程
C28: 借款额 | D28: =D16 -> 0 | E28: =E16 -> 8743.51 | F28: =F16 -> 4371.755 | G28: =G16 -> 4371.755 | H28: =H16 -> 4371.755 | I28: =I16 -> 4371.755 | J28: =J16 -> 4371.755 | K28: =K16 -> 4371.755 | ... N28: =N16 -> 0 | O28: 合计
C29: 借款利息 | D29: =D28*0.5*'0基本假设 '!L34 -> 0 | E29: =D28*'0基本假设 '!L34+E28*'0基本假设 '!L34/2 -> 65.576325 | F29: =SUM($E$28:E28)*'0基本假设 '!$L$34+F28*'0基本假设 '!$L$34/2 -> 163.94081 | G29: =SUM($E$28:F28)*'0基本假设 '!$L$34+G28*'0基本假设 '!$L$34/2 -> 229.51714 | H29: =SUM($E$28:G28)*'0基本假设 '!$L$34+H28*'0基本假设 '!$L$34/2 -> 295.09346 | I29: =SUM($E$28:H28)*'0基本假设 '!$L$34+I28*'0基本假设 '!$L$34/2 -> 360.66979 | J29: =SUM($E$28:I28)*'0基本假设 '!$L$34+J28*'0基本假设 '!$L$34/2 -> 426.24611 | K29: =SUM($E$28:J28)*'0基本假设 '!$L$34+K28*'0基本假设 '!$L$34/2 -> 491.82244 | L29: =SUM($E$28:K28)*'0基本假设 '!$L$34+L28*'0基本假设 '!$L$34/2 -> 557.39876 | M29: =SUM($E$28:L28)*'0基本假设 '!$L$34+M28*'0基本假设 '!$L$34/2 -> 622.97509 | N29: 0 | O29: =SUM(D29:M29) -> 3213.2399
C30: 投资贷款节奏 | D30: =R5 -> 0.56042074 | E30: =S5 -> 0.082510686 | F30: =T5 -> 0.04248379 | G30: =U5 -> 0.043098014 | H30: =V5 -> 0.043712237 | I30: =W5 -> 0.04432646 | J30: =X5 -> 0.044940684 | K30: =Y5 -> 0.045554907 | ... M30: =AA5 -> 0.046783354 | O30: =SUM(D30:M30) -> 1
B31: 点击返回目录

Sheet 附表3营业收入汇总表
A1: 附表4 营业收入明细表 (单位：万元)
A2: 序号 | B2: 项目 | C2: 合计 | D2: 第1年Q1 | E2: 第1年Q2 | F2: 第1年Q3 | G2: 第1年Q4 | H2: 第2年Q1 | I2: 第2年Q2 | J2: 第2年Q3 | K2: 第2年Q4 | L2: 第3年Q1 | M2: 第3年Q2 | N2: 第3年Q3 | O2: 第3年Q4 | P2: 第4年Q1 | Q2: 第4年Q2 | R2: 第4年Q3 | S2: 第4年Q4 | T2: 第5年Q1 | U2: 第5年Q2 | V2: 第5年Q3 | W2: 第5年Q4
A3: 1 | B3: 收入合计 | C3: =SUM(D3:W3) -> 115945.07 | D3: =D4+D6 -> 0 | E3: =E4+E6 -> 0 | F3: =F4+F6 -> 0 | G3: =G4+G6 -> 23989.014 | H3: =H4+H6 -> 9345.6058 | I3: =I4+I6 -> 9345.6058 | J3: =J4+J6 -> 12943.958 | K3: =K4+K6 -> 6946.7043 | ... W3: =W4+W6 -> 26137.916
A4: 1.1 | B4: 销售收入 | C4: =SUM(D4:W4) -> 115945.07 | D4: =D5 -> 0 | E4: =E5 -> 0 | F4: =F5 -> 0 | G4: =G5 -> 23989.014 | H4: =H5 -> 9345.6058 | I4: =I5 -> 9345.6058 | J4: =J5 -> 12943.958 | K4: =K5 -> 6946.7043 | ... W4: =W5 -> 26137.916
B5: 其中：销售收入 | C5: =SUM(D5:W5) -> 115945.07 | D5: ='3.1销售情况分析'!G6 -> 0 | E5: ='3.1销售情况分析'!H6 -> 0 | F5: ='3.1销售情况分析'!I6 -> 0 | G5: ='3.1销售情况分析'!J6 -> 23989.014 | H5: ='3.1销售情况分析'!K6 -> 9345.6058 | I5: ='3.1销售情况分析'!L6 -> 9345.6058 | J5: ='3.1销售情况分析'!M6 -> 12943.958 | K5: ='3.1销售情况分析'!N6 -> 6946.7043 | ... W5: ='3.1销售情况分析'!Z6 -> 26137.916
A6: 1.2 | B6: 土地款返还收入 | C6: =SUM(D6:W6) -> 0 | D6: ='3.2 营业收入汇总表'!D9 -> 0 | E6: ='3.2 营业收入汇总表'!E9 -> 0 | F6: ='3.2 营业收入汇总表'!F9 -> 0 | G6: ='3.2 营业收入汇总表'!G9 -> 0 | H6: ='3.2 营业收入汇总表'!H9 -> 0 | I6: ='3.2 营业收入汇总表'!I9 -> 0 | J6: ='3.2 营业收入汇总表'!J9 -> 0 | K6: ='3.2 营业收入汇总表'!K9 -> 0 | ... W6: ='3.2 营业收入汇总表'!W9 -> 0
A8: 点击返回目录
B9: 项目基础数据
B10: 规划数据 | C10: 数据值 | D10: 备 注
B11: 总用地面积（m²） | C11: 23384.4 | D11: 约35.1亩
B12: 总建筑面积（m²） | C12: 134746.85
B13: 计容建筑面积（m²） | C13: 104467.85
B14: 其中：住宅（m²） | C14: 86949.32
B15: 商业（m²） | C15: 16178.53
B16: 地下建筑面积（m²） | C16: 30279
B17: 其中：车位（个） | C17: 796
B18: 可售物业 | C18: 数 量 | D18: 备 注
B19: 车位（个） | C19: 736 | D19: 共796个，返村60个
B20: 商业（m²） | C20: 6178.53 | D20: 共16178.53平方，返村10000平方
B21: 住宅（m²） | C21: 86949.32
B24: 收入测算
B25: 项 目 | C25: 总物业 | D25: 减返村物业 | E25: 可售物业 | F25: 单 价（元/平米） | G25: 销售收入
B26: 车位（个） | C26: 796 | D26: 60 | E26: 736 | F26: 120000 | G26: =E26*F26 -> 88320000
B27: 商业（m²） | C27: 16178.53 | D27: 10000 | E27: 6178.53 | F27: 20000 | G27: =E27*F27 -> 123570600
B28: 住宅（m²） | C28: 86949.32 | D28: 0 | E28: 86949.32 | F28: 13000 | G28: =E28*F28 -> 1130341160
B29: 合 计 | G29: =SUM(G26:G28) -> 1342231760
B32: 成本测算
B33: 明细项目 | C33: 计算基数 | D33: 单位成本 | E33: 预算总成本（元） | F33: 计算依据
B34: 一、土地费用 | C34: 104467.85 | D34: =E34/C34 -> 5727.4094 | E34: =SUM(E35:E38) -> 598330150 | F34: 1+2+3
B35: 1、土地出让金 | E35: 527700000 | F35: 挂牌起始价52770万
B36: 2、契税 | E36: =E35*0.04 -> 21108000 | F36: 土地出让金的4% | G36: 请提供明细和税率
B37: 3、印花税 | E37: =E35*0.0005 -> 263850 | F37: 土地出让金的0.05%
B38: 4、教育配套费 | E38: 49258300
B39: 二、前期费用 | E39: 31192548 | F39: 4+5 | G39: 请确认
B40: 4、报批报建 | E40: 28497611
B41: 5、规划设计 | E41: 2694937 | F41: 参考同行项目
B42: 三、建安和基础设施配套 | C42: 134746.85 | D42: 3000 | E42: =C42*D42 -> 404240550 | G42: 请提供明细
B46: 四、管理费用 | D46: 0.005 | E46: =G10*0.005 -> 0 | F46: 按总销售收入的0.5%测算
B47: 1、工资 | G47: 请提供明细
B48: 2、其他
...

Sheet 3.1销售情况分析
B1: 附表3.1 销售收入-汇总（万元）
B2: 序号 | C2: 项目 | D2: 备注 | E2: 收入占比 | F2: 合计 | G2: 第1年Q1 | H2: 第1年Q2 | I2: 第1年Q3 | J2: 第1年Q4 | K2: 第2年Q1 | L2: 第2年Q2 | M2: 第2年Q3 | N2: 第2年Q4 | O2: 第3年Q1 | P2: 第3年Q2 | Q2: 第3年Q3 | R2: 第3年Q4 | S2: 第4年Q1 | T2: 第4年Q2 | U2: 第4年Q3 | V2: 第4年Q4 | W2: 第5年Q1 | X2: 第5年Q2 | Y2: 第5年Q3 | Z2: 第5年Q4
B3: 1 | C3: 含税销售收入合计 | F3: =SUM(G3:Z3) -> 115945.07 | G3: =SUM(G6) -> 0 | H3: =SUM(H6) -> 0 | I3: =SUM(I6) -> 0 | J3: =SUM(J6) -> 23989.014 | K3: =SUM(K6) -> 9345.6058 | L3: =SUM(L6) -> 9345.6058 | M3: =SUM(M6) -> 12943.958 | N3: =SUM(N6) -> 6946.7043 | ... Z3: =SUM(Z6) -> 26137.916
B4: 2 | C4: 税金及附加 | F4: =SUM(G4:Z4) -> 921.96832 | G4: =G33+G34+'附表4 税金及附加表'!F6 -> 0 | H4: =H33+H34+'附表4 税金及附加表'!G6 -> 0 | I4: =I33+I34+'附表4 税金及附加表'!H6 -> 0 | J4: =J33+J34+'附表4 税金及附加表'!I6 -> 0 | K4: =K33+K34+'附表4 税金及附加表'!J6 -> 0 | L4: =L33+L34+'附表4 税金及附加表'!K6 -> 0 | M4: =M33+M34+'附表4 税金及附加表'!L6 -> 0 | N4: =N33+N34+'附表4 税金及附加表'!M6 -> 0 | ... Z4: =Z33+Z34+'附表4 税金及附加表'!Y6 -> 921.96832
B5: 3 | C5: 不含税收入 | F5: =SUM(G5:Z5) -> 115023.1 | G5: =G3-G4 -> 0 | H5: =H3-H4 -> 0 | I5: =I3-I4 -> 0 | J5: =J3-J4 -> 23989.014 | K5: =K3-K4 -> 9345.6058 | L5: =L3-L4 -> 9345.6058 | M5: =M3-M4 -> 12943.958 | N5: =N3-N4 -> 6946.7043 | ... Z5: =Z3-Z4 -> 25215.948
B6: 3.1 | C6: 销售收入（缺口承担后） | F6: =SUM(G6:Z6) -> 115945.07 | G6: =SUM(G7:G9) -> 0 | H6: =SUM(H7:H9) -> 0 | I6: =SUM(I7:I9) -> 0 | J6: =SUM(J7:J9) -> 23989.014 | K6: =SUM(K7:K9) -> 9345.6058 | L6: =SUM(L7:L9) -> 9345.6058 | M6: =SUM(M7:M9) -> 12943.958 | N6: =SUM(N7:N9) -> 6946.7043 | ... P6: =SUM(P7:P9) -> 3348.3522 | Q6: =SUM(Q7:Q9)+Q10 -> 2148.9014 | R6: =SUM(R7:R9)+R10 -> 2148.9014 | S6: =SUM(S7:S9)+S10 -> 2148.9014 | T6: =SUM(T7:T9)+T10 -> 2148.9014 | U6: =SUM(U7:U9)+U10 -> 2148.9014 | V6: =SUM(V7:V9)+V10 -> 2148.9014 | W6: =SUM(W7:W9)+W10 -> 2148.9014 | X6: =SUM(X7:X9)+X10 -> 2148.9014 | ... Z6: =SUM(Z7:Z9)+Z10 -> 26137.916
B8: 3.1.1 | C8: 五江项目 | F8: =SUM(G8:Z8) -> 115945.07 | G8: =SUM(G79:G81) -> 0 | H8: =SUM(H79:H81) -> 0 | I8: =SUM(I79:I81) -> 0 | J8: =SUM(J79:J81) -> 23989.014 | K8: =SUM(K79:K81) -> 9345.6058 | L8: =SUM(L79:L81) -> 9345.6058 | M8: =SUM(M79:M81) -> 12943.958 | N8: =SUM(N79:N81) -> 6946.7043 | ... Z8: =SUM(Z79:Z81) -> 26137.916
F9: =SUM(G9:Z9) -> 0
B10: 3.1.2 | C10: 土地款返还收入 | F10: =SUM(G10:Z10) -> 0
C11: 真实经营性收入
B13: 附表3.2 增值税及附加测算（万元）
B14: 序号 | C14: 项目 | D14: 税率 | E14: 合计 | F14: 合计 | G14: 第1年Q1 | H14: 第1年Q2 | I14: 第1年Q3 | J14: 第1年Q4 | K14: 第2年Q3 | L14: 第2年Q4 | M14: 第3年Q1 | N14: 第3年Q2 | O14: 第3年Q3 | P14: 第3年Q4 | Q14: 第4年Q1 | R14: 第4年Q2 | S14: 第4年Q3 | T14: 第4年Q4 | U14: 第6年Q3 | V14: 第6年Q4 | W14: 第7年Q1 | X14: 第7年Q2 | Y14: 第7年Q3 | Z14: 第7年Q4
B15: 1 | C15: 项目公司营业收入 | E15: =SUM(G15:AD15) -> 115945.07 | F15: =SUM(G15:Z15) -> 115945.07 | G15: =G16+G19 -> 0 | H15: =H16+H19 -> 0 | I15: =I16+I19 -> 0 | J15: =J16+J19 -> 23989.014 | K15: =K16+K19 -> 9345.6058 | L15: =L16+L19 -> 9345.6058 | M15: =M16+M19 -> 12943.958 | N15: =N16+N19 -> 6946.7043 | ... Z15: =Z16+Z19 -> 26137.916
B16: 1.1 | C16: 销售收入 | E16: =SUM(G16:AD16) -> 115945.07 | F16: =SUM(G16:Z16) -> 115945.07 | G16: =G6 -> 0 | H16: =H6 -> 0 | I16: =I6 -> 0 | J16: =J6 -> 23989.014 | K16: =K6 -> 9345.6058 | L16: =L6 -> 9345.6058 | M16: =M6 -> 12943.958 | N16: =N6 -> 6946.7043 | ... Z16: =Z6 -> 26137.916
B17: 1.1.1 | C17: 物业管理费 | E17: =SUM(G17:AD17) -> 0 | F17: =SUM(G17:Z17) -> 0 | G17: 0 | H17: 0 | I17: 0 | P17: 0 | Q17: 0 | R17: 0 | S17: 0 | T17: 0 | W17: 0 | X17: 0 | Y17: 0 | Z17: 0
B18: 1.1.2 | C18: 其他合计 | E18: =SUM(G18:AD18) -> 0 | F18: =SUM(G18:Z18) -> 0 | G18: 0 | H18: 0 | I18: 0 | P18: 0 | Q18: 0 | R18: 0 | S18: 0 | T18: 0 | W18: 0 | X18: 0 | Y18: 0 | Z18: 0
B19: 1.2 | C19: 土地款返还收入 | E19: =SUM(G19:AD19) -> 0 | F19: =SUM(G19:Z19) -> 0 | G19: =G10 -> 0 | H19: =H10 -> 0 | I19: =I10 -> 0 | J19: =J10 -> 0 | K19: =K10 -> 0 | L19: =L10 -> 0 | M19: =M10 -> 0 | N19: =N10 -> 0 | ... Z19: =Z10 -> 0
B20: 2 | C20: 增值税-销项税额 | E20: =SUM(G20:AD20) -> 9573.4463 | F20: =SUM(G20:Z20) -> 9573.4463 | G20: =G21+G24 -> 0 | H20: =H21+H24 -> 0 | I20: =I21+I24 -> 0 | J20: =J21+J24 -> 1980.7443 | K20: =K21+K24 -> 771.65552 | L20: =L21+L24 -> 771.65552 | M20: =M21+M24 -> 1068.7672 | N20: =N21+N24 -> 573.58109 | ... Z20: =Z21+Z24 -> 2158.1765
B21: 2.1 | C21: 销售收入 | D21: 0.09 | E21: =SUM(G21:AD21) -> 9573.4463 | F21: =SUM(G21:Z21) -> 9573.4463 | G21: =G16/(1+$D$21)*$D$21 -> 0 | H21: =H16/(1+$D$21)*$D$21 -> 0 | I21: =I16/(1+$D$21)*$D$21 -> 0 | J21: =J16/(1+$D$21)*$D$21 -> 1980.7443 | K21: =K16/(1+$D$21)*$D$21 -> 771.65552 | L21: =L16/(1+$D$21)*$D$21 -> 771.65552 | M21: =M16/(1+$D$21)*$D$21 -> 1068.7672 | N21: =N16/(1+$D$21)*$D$21 -> 573.58109 | ... Z21: =Z16/(1+$D$21)*$D$21 -> 2158.1765
B22: 2.1.1 | C22: 物业管理费 | E22: =SUM(G22:AD22) -> #REF! | F22: =SUM(G22:Z22) -> #REF! | G22: =G17/(1+#REF!)*#REF! -> #REF! | H22: =H17/(1+#REF!)*#REF! -> #REF! | I22: =I17/(1+#REF!)*#REF! -> #REF! | P22: =P17/(1+#REF!)*#REF! -> #REF! | Q22: =Q17/(1+#REF!)*#REF! -> #REF! | R22: =R17/(1+#REF!)*#REF! -> #REF! | S22: =S17/(1+#REF!)*#REF! -> #REF! | T22: =T17/(1+#REF!)*#REF! -> #REF! | W22: =W17/(1+#REF!)*#REF! -> #REF! | X22: =X17/(1+#REF!)*#REF! -> #REF! | Y22: =Y17/(1+#REF!)*#REF! -> #REF! | Z22: =Z17/(1+#REF!)*#REF! -> #REF!
B23: 2.1.2 | C23: 其他合计 | E23: =SUM(G23:AD23) -> #REF! | F23: =SUM(G23:Z23) -> #REF! | G23: =G18/(1+#REF!)*#REF! -> #REF! | H23: =H18/(1+#REF!)*#REF! -> #REF! | I23: =I18/(1+#REF!)*#REF! -> #REF! | P23: =P18/(1+#REF!)*#REF! -> #REF! | Q23: =Q18/(1+#REF!)*#REF! -> #REF! | R23: =R18/(1+#REF!)*#REF! -> #REF! | S23: =S18/(1+#REF!)*#REF! -> #REF! | T23: =T18/(1+#REF!)*#REF! -> #REF! | W23: =W18/(1+#REF!)*#REF! -> #REF! | X23: =X18/(1+#REF!)*#REF! -> #REF! | Y23: =Y18/(1+#REF!)*#REF! -> #REF! | Z23: =Z18/(1+#REF!)*#REF! -> #REF!
B24: 2.2 | C24: 土地款返还收入 | E24: =SUM(G24:AD24) -> 0 | F24: =SUM(G24:Z24) -> 0 | G24: =G19/(1+$D$24)*$D$24 -> 0 | H24: =H19/(1+$D$24)*$D$24 -> 0 | I24: =I19/(1+$D$24)*$D$24 -> 0 | J24: =J19/(1+$D$24)*$D$24 -> 0 | K24: =K19/(1+$D$24)*$D$24 -> 0 | L24: =L19/(1+$D$24)*$D$24 -> 0 | M24: =M19/(1+$D$24)*$D$24 -> 0 | N24: =N19/(1+$D$24)*$D$24 -> 0 | ... Z24: =Z19/(1+$D$24)*$D$24 -> 0
B25: 3 | C25: 增值税-进项税额 | E25: =SUM(G25:AD25) -> 8735.2933 | F25: =SUM(G25:Z25) -> 8735.2933 | G25: =G26+G27+G28+G29 -> 4940.2722 | H25: =H26+H27+H28+H29 -> 721.94119 | I25: =I26+I27+I28+I29 -> 360.9706 | J25: =J26+J27+J28+J29 -> 360.9706 | K25: =K26+K27+K28+K29 -> 360.9706 | L25: =L26+L27+L28+L29 -> 360.9706 | M25: =M26+M27+M28+M29 -> 360.9706 | N25: =N26+N27+N28+N29 -> 360.9706 | ... Z25: =Z26+Z27+Z28+Z29 -> 79.635611
B26: 3.1 | C26: 工程建设 | D26: 0.09 | E26: =SUM(G26:Q26) -> 3352.0913 | F26: =SUM(G26:Z26) -> 3352.0913 | G26: ='附表2 投资计划与资金筹措平衡表 '!D6*'3.1销售情况分析'!$D$26/(1+'3.1销售情况分析'!$D$26) -> 0 | H26: ='附表2 投资计划与资金筹措平衡表 '!E6*'3.1销售情况分析'!$D$26/(1+'3.1销售情况分析'!$D$26) -> 670.41826 | I26: ='附表2 投资计划与资金筹措平衡表 '!F6*'3.1销售情况分析'!$D$26/(1+'3.1销售情况分析'!$D$26) -> 335.20913 | J26: ='附表2 投资计划与资金筹措平衡表 '!G6*'3.1销售情况分析'!$D$26/(1+'3.1销售情况分析'!$D$26) -> 335.20913 | K26: ='附表2 投资计划与资金筹措平衡表 '!H6*'3.1销售情况分析'!$D$26/(1+'3.1销售情况分析'!$D$26) -> 335.20913 | L26: ='附表2 投资计划与资金筹措平衡表 '!I6*'3.1销售情况分析'!$D$26/(1+'3.1销售情况分析'!$D$26) -> 335.20913 | M26: ='附表2 投资计划与资金筹措平衡表 '!J6*'3.1销售情况分析'!$D$26/(1+'3.1销售情况分析'!$D$26) -> 335.20913 | N26: ='附表2 投资计划与资金筹措平衡表 '!K6*'3.1销售情况分析'!$D$26/(1+'3.1销售情况分析'!$D$26) -> 335.20913 | ... P26: ='附表2 投资计划与资金筹措平衡表 '!M6*'3.1销售情况分析'!$D$26/(1+'3.1销售情况分析'!$D$26) -> 335.20913
B27: 3.2 | C27: 工程建设其他费用 | D27: 0.09 | E27: =SUM(G27:Q27) -> 5197.8868 | F27: =SUM(G27:Z27) -> 5197.8868 | G27: ='附表2 投资计划与资金筹措平衡表 '!D7*'3.1销售情况分析'!$D$27/(1+'3.1销售情况分析'!$D$27) -> 4940.2722 | H27: ='附表2 投资计划与资金筹措平衡表 '!E7*'3.1销售情况分析'!$D$27/(1+'3.1销售情况分析'!$D$27) -> 51.522936 | I27: ='附表2 投资计划与资金筹措平衡表 '!F7*'3.1销售情况分析'!$D$27/(1+'3.1销售情况分析'!$D$27) -> 25.761468 | J27: ='附表2 投资计划与资金筹措平衡表 '!G7*'3.1销售情况分析'!$D$27/(1+'3.1销售情况分析'!$D$27) -> 25.761468 | K27: ='附表2 投资计划与资金筹措平衡表 '!H7*'3.1销售情况分析'!$D$27/(1+'3.1销售情况分析'!$D$27) -> 25.761468 | L27: ='附表2 投资计划与资金筹措平衡表 '!I7*'3.1销售情况分析'!$D$27/(1+'3.1销售情况分析'!$D$27) -> 25.761468 | M27: ='附表2 投资计划与资金筹措平衡表 '!J7*'3.1销售情况分析'!$D$27/(1+'3.1销售情况分析'!$D$27) -> 25.761468 | N27: ='附表2 投资计划与资金筹措平衡表 '!K7*'3.1销售情况分析'!$D$27/(1+'3.1销售情况分析'!$D$27) -> 25.761468 | ... P27: ='附表2 投资计划与资金筹措平衡表 '!M7*'3.1销售情况分析'!$D$27/(1+'3.1销售情况分析'!$D$27) -> 25.761468 | T27: ='附表2 投资计划与资金筹措平衡表 '!Q7*'3.1销售情况分析'!$D$27/(1+'3.1销售情况分析'!$D$27) -> 0 | U27: ='附表2 投资计划与资金筹措平衡表 '!X7*'3.1销售情况分析'!$D$27/(1+'3.1销售情况分析'!$D$27) -> 0 | V27: ='附表2 投资计划与资金筹措平衡表 '!Y7*'3.1销售情况分析'!$D$27/(1+'3.1销售情况分析'!$D$27) -> 0 | W27: ='附表2 投资计划与资金筹措平衡表 '!Z7*'3.1销售情况分析'!$D$27/(1+'3.1销售情况分析'!$D$27) -> 0 | X27: ='附表2 投资计划与资金筹措平衡表 '!AA7*'3.1销售情况分析'!$D$27/(1+'3.1销售情况分析'!$D$27) -> 0 | Y27: ='附表2 投资计划与资金筹措平衡表 '!AB7*'3.1销售情况分析'!$D$27/(1+'3.1销售情况分析'!$D$27) -> 0 | Z27: ='附表2 投资计划与资金筹措平衡表 '!AC7*'3.1销售情况分析'!$D$27/(1+'3.1销售情况分析'!$D$27) -> 0
B28: 3.3 | C28: 预备费 | D28: 0.06 | E28: =SUM(G28:Q28) -> 0 | F28: =SUM(G28:Z28) -> 0
B29: 3.4 | C29: 运维经营成本进项税 | D29: 0.06 | E29: =SUM(G29:AD29) -> 185.31518 | F29: =SUM(G29:Z29) -> 185.31518 | Q29: ='5.1运营成本明细表'!Q3/(1+'3.1销售情况分析'!$D$29)*'3.1销售情况分析'!$D$29 -> 11.742174 | R29: ='5.1运营成本明细表'!R3/(1+'3.1销售情况分析'!$D$29)*'3.1销售情况分析'!$D$29 -> 11.742174 | S29: ='5.1运营成本明细表'!S3/(1+'3.1销售情况分析'!$D$29)*'3.1销售情况分析'!$D$29 -> 11.742174 | T29: ='5.1运营成本明细表'!T3/(1+'3.1销售情况分析'!$D$29)*'3.1销售情况分析'!$D$29 -> 11.742174 | U29: ='5.1运营成本明细表'!U3/(1+'3.1销售情况分析'!$D$29)*'3.1销售情况分析'!$D$29 -> 11.742174 | V29: ='5.1运营成本明细表'!V3/(1+'3.1销售情况分析'!$D$29)*'3.1销售情况分析'!$D$29 -> 11.742174 | W29: ='5.1运营成本明细表'!W3/(1+'3.1销售情况分析'!$D$29)*'3.1销售情况分析'!$D$29 -> 11.742174 | X29: ='5.1运营成本明细表'!X3/(1+'3.1销售情况分析'!$D$29)*'3.1销售情况分析'!$D$29 -> 11.742174 | ... Z29: ='5.1运营成本明细表'!Z3/(1+'3.1销售情况分析'!$D$29)*'3.1销售情况分析'!$D$29 -> 79.635611
B30: 4 | C30: 当期留抵进项税额 | E30: =SUM(G30:AD30) -> 6107.6851 | F30: =SUM(G30:Z30) -> 6107.6851 | G30: =IF(G25>G20,G25-G20,0) -> 4940.2722 | H30: =IF(H25>H20,H25-H20,0) -> 721.94119 | I30: =IF(I25>I20,I25-I20,0) -> 360.9706 | J30: =IF(J25>J20,J25-J20,0) -> 0 | K30: =IF(K25>K20,K25-K20,0) -> 0 | L30: =IF(L25>L20,L25-L20,0) -> 0 | M30: =IF(M25>M20,M25-M20,0) -> 0 | N30: =IF(N25>N20,N25-N20,0) -> 0 | ... Z30: =IF(Z25>Z20,Z25-Z20,0) -> 0
B31: 5 | C31: 前期留抵进项税抵扣当期销项税额 | E31: =SUM(G31:AD31) -> 6107.6851 | F31: =SUM(G31:Z31) -> 6107.6851 | J31: =IF(AND(I32>0,J30=0),IF(I32>ABS(J20-J25),ABS(J25-J20),I32),0) -> 1619.7737 | K31: =IF(AND(J32>0,K30=0),IF(J32>ABS(K20-K25),ABS(K25-K20),J32),0) -> 410.68493 | L31: =IF(AND(K32>0,L30=0),IF(K32>ABS(L20-L25),ABS(L25-L20),K32),0) -> 410.68493 | M31: =IF(AND(L32>0,M30=0),IF(L32>ABS(M20-M25),ABS(M25-M20),L32),0) -> 707.79657 | N31: =IF(AND(M32>0,N30=0),IF(M32>ABS(N20-N25),ABS(N25-N20),M32),0) -> 212.61049 | O31: =IF(AND(N32>0,O30=0),IF(N32>ABS(O20-O25),ABS(O25-O20),N32),0) -> 14.536063 | P31: =IF(AND(O32>0,P30=0),IF(O32>ABS(P20-P25),ABS(P25-P20),O32),0) -> 0 | Q31: =IF(AND(P32>0,Q30=0),IF(P32>ABS(Q20-Q25),ABS(Q25-Q20),P32),0) -> 165.69006 | ... Z31: =IF(AND(Y32>0,Z30=0),IF(Y32>ABS(Z20-Z25),ABS(Z25-Z20),Y32),0) -> 1240.3879
B32: 6 | C32: 剩余留抵进项税额 | E32: =SUM(G32:AD32) -> 56646.751 | G32: =G30 -> 4940.2722 | H32: =G32+H30-H31 -> 5662.2133 | I32: =H32+I30-I31 -> 6023.1839 | J32: =I32+J30-J31 -> 4403.4102 | K32: =J32+K30-K31 -> 3992.7253 | L32: =K32+L30-L31 -> 3582.0404 | M32: =L32+M30-M31 -> 2874.2438 | N32: =M32+N30-N31 -> 2661.6333 | O32: =N32+O30-O31 -> 2647.0973 | ... Z32: =Y32+Z30-Z31 -> 0
B33: 7 | C33: 当期缴纳增值税 | E33: =SUM(G33:AD33) -> 838.15302 | F33: =SUM(G33:Z33) -> 838.15302 | G33: =IF(G30>0,0,G20-G25-G31) -> 0 | H33: =IF(H30>0,0,H20-H25-H31) -> 0 | I33: =IF(I30>0,0,I20-I25-I31) -> 0 | J33: =IF(J30>0,0,J20-J25-J31) -> 0 | K33: =IF(K30>0,0,K20-K25-K31) -> 0 | L33: =IF(L30>0,0,L20-L25-L31) -> 0 | M33: =IF(M30>0,0,M20-M25-M31) -> 0 | N33: =IF(N30>0,0,N20-N25-N31) -> 0 | ... Z33: =IF(Z30>0,0,Z20-Z25-Z31) -> 838.15302
B34: 8 | C34: 增值税附加 | E34: =SUM(G34:AD34) -> 83.815302 | F34: =SUM(G34:Z34) -> 83.815302 | G34: =G35+G36 -> 0 | H34: =H35+H36 -> 0 | I34: =I35+I36 -> 0 | J34: =J35+J36 -> 0 | K34: =K35+K36 -> 0 | L34: =L35+L36 -> 0 | M34: =M35+M36 -> 0 | N34: =N35+N36 -> 0 | ... Z34: =Z35+Z36 -> 83.815302
B35: 8.1 | C35: 城建税 | D35: 0.07 | E35: =SUM(G35:AD35) -> 58.670711 | F35: =SUM(G35:Z35) -> 58.670711 | G35: =G34*$D$35 -> 0 | H35: =H33*$D$35 -> 0 | I35: =I33*$D$35 -> 0 | J35: =J33*$D$35 -> 0 | K35: =K33*$D$35 -> 0 | L35: =L33*$D$35 -> 0 | M35: =M33*$D$35 -> 0 | N35: =N33*$D$35 -> 0 | O35: =O33*$D$35 -> 0 | ... Z35: =Z33*$D$35 -> 58.670711
B36: 8.2 | C36: 教育附加费 | D36: 0.03 | E36: =SUM(G36:AD36) -> 25.144591 | F36: =SUM(G36:Z36) -> 25.144591 | G36: 0 | H36: =H33*$D$36 -> 0 | I36: =I33*$D$36 -> 0 | J36: =J33*$D$36 -> 0 | K36: =K33*$D$36 -> 0 | L36: =L33*$D$36 -> 0 | M36: =M33*$D$36 -> 0 | N36: =N33*$D$36 -> 0 | O36: =O33*$D$36 -> 0 | ... Z36: =Z33*$D$36 -> 25.144591
B38: 序号 | C38: 项目 | D38: 备注 | E38: 收入占比 | F38: 合计 | G38: 第1年Q1 | H38: 第1年Q2 | I38: 第1年Q3 | J38: 第1年Q4 | K38: 第2年Q3 | L38: 第2年Q4 | M38: 第3年Q1 | N38: 第3年Q2 | O38: 第3年Q3 | P38: 第3年Q4 | Q38: 第4年Q1 | R38: 第4年Q2 | S38: 第4年Q3 | T38: 第4年Q4 | U38: 第6年Q3 | V38: 第6年Q4 | W38: 第7年Q1 | X38: 第7年Q2 | Y38: 第7年Q3 | Z38: 第7年Q4
B39: 1 | C39: 销售百分比 | F39: =SUM(G39:Z39) -> 1 | G39: ='3.1销售情况分析'!G42/'3.1销售情况分析'!$F$42 -> 0 | H39: ='3.1销售情况分析'!H42/'3.1销售情况分析'!$F$42 -> 0 | I39: ='3.1销售情况分析'!I42/'3.1销售情况分析'!$F$42 -> 0 | J39: ='3.1销售情况分析'!J42/'3.1销售情况分析'!$F$42 -> 0.20689982 | K39: ='3.1销售情况分析'!K42/'3.1销售情况分析'!$F$42 -> 0.080603734 | L39: ='3.1销售情况分析'!L42/'3.1销售情况分析'!$F$42 -> 0.080603734 | M39: ='3.1销售情况分析'!M42/'3.1销售情况分析'!$F$42 -> 0.11163871 | N39: ='3.1销售情况分析'!N42/'3.1销售情况分析'!$F$42 -> 0.059913752 | ... Z39: ='3.1销售情况分析'!Z42/'3.1销售情况分析'!$F$42 -> 0.22543361
B40: 附表3.3 土增税（万元）
B41: 序号 | C41: 项目 | D41: 备注 | E41: 合计 | F41: 合计 | G41: 第1年Q1 | H41: 第1年Q2 | I41: 第1年Q3 | J41: 第1年Q4 | K41: 第2年Q3 | L41: 第2年Q4 | M41: 第3年Q1 | N41: 第3年Q2 | O41: 第3年Q3 | P41: 第3年Q4 | Q41: 第4年Q1 | R41: 第4年Q2 | S41: 第4年Q3 | T41: 第4年Q4 | U41: 第6年Q3 | V41: 第6年Q4 | W41: 第7年Q1 | X41: 第7年Q2 | Y41: 第7年Q3 | Z41: 第7年Q4
B42: 1 | C42: 营业收入合计（不含税） | E42: =SUM(G42:Z42) -> 106371.63 | F42: =SUM(G42:Z42) -> 106371.63 | G42: =G43+G44 -> 0 | H42: =H43+H44 -> 0 | I42: =I43+I44 -> 0 | J42: =J43+J44 -> 22008.27 | K42: =K43+K44 -> 8573.9502 | L42: =L43+L44 -> 8573.9502 | M42: =M43+M44 -> 11875.191 | N42: =N43+N44 -> 6373.1232 | ... Z42: =Z43+Z44 -> 23979.739
B43: 1.1 | C43: 销售收入（不含税） | D43: 不含税 | E43: =SUM(G43:Z43) -> 106371.63 | F43: =SUM(G43:Z43) -> 106371.63 | G43: ='3.1销售情况分析'!G16-'3.1销售情况分析'!G21 -> 0 | H43: ='3.1销售情况分析'!H16-'3.1销售情况分析'!H21 -> 0 | I43: ='3.1销售情况分析'!I16-'3.1销售情况分析'!I21 -> 0 | J43: ='3.1销售情况分析'!J16-'3.1销售情况分析'!J21 -> 22008.27 | K43: ='3.1销售情况分析'!K16-'3.1销售情况分析'!K21 -> 8573.9502 | L43: ='3.1销售情况分析'!L16-'3.1销售情况分析'!L21 -> 8573.9502 | M43: ='3.1销售情况分析'!M16-'3.1销售情况分析'!M21 -> 11875.191 | N43: ='3.1销售情况分析'!N16-'3.1销售情况分析'!N21 -> 6373.1232 | ... Z43: ='3.1销售情况分析'!Z16-'3.1销售情况分析'!Z21 -> 23979.739
...

Sheet 3.2 营业收入汇总表
A1: 附表4 营业收入汇总表(单位：万元)
A2: 序号 | B2: 项目 | C2: 小计 | D2: 第1年Q1 | E2: 第1年Q2 | F2: 第1年Q3 | G2: 第1年Q4 | H2: 第2年Q1 | I2: 第2年Q2 | J2: 第2年Q3 | K2: 第2年Q4 | L2: 第3年Q1 | M2: 第3年Q2 | N2: 第3年Q3 | O2: 第3年Q4 | P2: 第4年Q1 | Q2: 第4年Q2 | R2: 第4年Q3 | S2: 第4年Q4 | T2: 第5年Q1 | U2: 第5年Q2 | V2: 第5年Q3 | W2: 第5年Q4
A3: 1 | B3: 含税销售收入 | C3: =SUM(D3:W3) -> 115945.07 | D3: ='3.1销售情况分析'!G3 -> 0 | E3: ='3.1销售情况分析'!H3 -> 0 | F3: ='3.1销售情况分析'!I3 -> 0 | G3: ='3.1销售情况分析'!J3 -> 23989.014 | H3: ='3.1销售情况分析'!K3 -> 9345.6058 | I3: ='3.1销售情况分析'!L3 -> 9345.6058 | J3: ='3.1销售情况分析'!M3 -> 12943.958 | K3: ='3.1销售情况分析'!N3 -> 6946.7043 | ... W3: ='3.1销售情况分析'!Z3 -> 26137.916
A4: 2 | B4: 增值税及附加 | C4: =SUM(D4:W4) -> 921.96832 | D4: ='3.1销售情况分析'!G4 -> 0 | E4: ='3.1销售情况分析'!H4 -> 0 | F4: ='3.1销售情况分析'!I4 -> 0 | G4: ='3.1销售情况分析'!J4 -> 0 | H4: ='3.1销售情况分析'!K4 -> 0 | I4: ='3.1销售情况分析'!L4 -> 0 | J4: ='3.1销售情况分析'!M4 -> 0 | K4: ='3.1销售情况分析'!N4 -> 0 | ... W4: ='3.1销售情况分析'!Z4 -> 921.96832
A5: 3 | B5: 不含税收入 | C5: =SUM(D5:W5) -> 115023.1 | D5: ='3.1销售情况分析'!G5 -> 0 | E5: ='3.1销售情况分析'!H5 -> 0 | F5: ='3.1销售情况分析'!I5 -> 0 | G5: ='3.1销售情况分析'!J5 -> 23989.014 | H5: ='3.1销售情况分析'!K5 -> 9345.6058 | I5: ='3.1销售情况分析'!L5 -> 9345.6058 | J5: ='3.1销售情况分析'!M5 -> 12943.958 | K5: ='3.1销售情况分析'!N5 -> 6946.7043 | ... W5: ='3.1销售情况分析'!Z5 -> 25215.948
A6: 5 | B6: 年经营成本 | C6: =SUM(D6:W6) -> 7697.2536 | D6: ='5.1运营成本明细表'!G3 -> 0 | E6: ='5.1运营成本明细表'!H3 -> 100 | F6: ='5.1运营成本明细表'!I3 -> 100 | G6: ='5.1运营成本明细表'!J3 -> 1299.4507 | H6: ='5.1运营成本明细表'!K3 -> 567.28029 | I6: ='5.1运营成本明细表'!L3 -> 567.28029 | J6: ='5.1运营成本明细表'!M3 -> 747.1979 | K6: ='5.1运营成本明细表'!N3 -> 447.33522 | ... W6: ='5.1运营成本明细表'!Z3 -> 1406.8958
A7: 6 | B7: 年经营合理利润 | C7: =SUM(D7:W7) -> 0 | D7: =D6*'0基本假设 '!$L$51 -> 0 | E7: =E6*'0基本假设 '!$L$51 -> 0 | F7: =F6*'0基本假设 '!$L$51 -> 0 | G7: =G6*'0基本假设 '!$L$51 -> 0 | H7: =H6*'0基本假设 '!$L$51 -> 0 | I7: =I6*'0基本假设 '!$L$51 -> 0 | J7: =J6*'0基本假设 '!$L$51 -> 0 | K7: =K6*'0基本假设 '!$L$51 -> 0 | ... W7: =W6*'0基本假设 '!$L$51 -> 0
A8: 7 | B8: 经营成本+经营合理利润 | C8: =SUM(D8:W8) -> 7697.2536 | D8: =D6+D7 -> 0 | E8: =E6+E7 -> 100 | F8: =F6+F7 -> 100 | G8: =G6+G7 -> 1299.4507 | H8: =H6+H7 -> 567.28029 | I8: =I6+I7 -> 567.28029 | J8: =J6+J7 -> 747.1979 | K8: =K6+K7 -> 447.33522 | ... W8: =W6+W7 -> 1406.8958
A9: 8 | B9: 土地出让金返还收入 | C9: =SUM(D9:W9) -> 0 | D9: ='3.1销售情况分析'!G19 -> 0 | E9: ='3.1销售情况分析'!H19 -> 0 | F9: ='3.1销售情况分析'!I19 -> 0 | G9: ='3.1销售情况分析'!J19 -> 0 | H9: ='3.1销售情况分析'!K19 -> 0 | I9: ='3.1销售情况分析'!L19 -> 0 | J9: ='3.1销售情况分析'!M19 -> 0 | K9: ='3.1销售情况分析'!N19 -> 0 | ... W9: ='3.1销售情况分析'!Z19 -> 0
B11: 折旧摊销系数 | C11: =SUM(D11:W11) -> 1 | D11: =D12+D13 -> 0 | E11: =E12+E13 -> 0 | F11: =F12+F13 -> 0 | G11: =G12+G13 -> 0.23689982 | H11: =H12+H13 -> 0.10060373 | I11: =I12+I13 -> 0.10060373 | J11: =J12+J13 -> 0.13163871 | K11: =K12+K13 -> 0.079913752 | ... W11: =W12+W13 -> 0.21043361
B12: 折旧摊销参考 | C12: =SUM(D12:W12) -> 1 | E12: =E3/$C$3 -> 0 | F12: =F3/$C$3 -> 0 | G12: =G3/$C$3 -> 0.20689982 | H12: =H3/$C$3 -> 0.080603734 | I12: =I3/$C$3 -> 0.080603734 | J12: =J3/$C$3 -> 0.11163871 | K12: =K3/$C$3 -> 0.059913752 | L12: =L3/$C$3 -> 0.03922377 | ... W12: =W3/$C$3 -> 0.22543361
B13: 折旧摊销调整系数 | C13: =SUM(D13:W13) -> 1.3877788e-17 | G13: 0.03 | H13: 0.02 | I13: 0.02 | J13: 0.02 | K13: 0.02 | L13: 0.02 | M13: 0.02 | N13: -0.015 | O13: -0.015 | P13: -0.015 | Q13: -0.015 | R13: -0.015 | S13: -0.015 | T13: -0.015 | U13: -0.015 | V13: -0.015 | W13: -0.015

Sheet 附表4 税金及附加表
B2: 附表4 税金及附加 (单位：万元)
B3: 序号 | C3: 项目 | E3: 合计 | F3: 第1年Q1 | G3: 第1年Q2 | H3: 第1年Q3 | I3: 第1年Q4 | J3: 第2年Q1 | K3: 第2年Q2 | L3: 第2年Q3 | M3: 第2年Q4 | N3: 第3年Q1 | O3: 第3年Q2 | P3: 第3年Q3 | Q3: 第3年Q4 | R3: 第4年Q1 | S3: 第4年Q2 | T3: 第4年Q3 | U3: 第4年Q4 | V3: 第5年Q1 | W3: 第5年Q2 | X3: 第5年Q3 | Y3: 第5年Q4
B4: 1.1 | C4: 销售收入（含税） | E4: =SUM(F4:Y4) -> 115945.07 | F4: ='3.1销售情况分析'!G3 -> 0 | G4: ='3.1销售情况分析'!H3 -> 0 | H4: ='3.1销售情况分析'!I3 -> 0 | I4: ='3.1销售情况分析'!J3 -> 23989.014 | J4: ='3.1销售情况分析'!K3 -> 9345.6058 | K4: ='3.1销售情况分析'!L3 -> 9345.6058 | L4: ='3.1销售情况分析'!M3 -> 12943.958 | M4: ='3.1销售情况分析'!N3 -> 6946.7043 | ... Y4: ='3.1销售情况分析'!Z3 -> 26137.916
B5: 2 | C5: 增值税及附加 | E5: =SUM(F5:Y5) -> 921.96832 | F5: ='3.1销售情况分析'!G33+'3.1销售情况分析'!G34 -> 0 | G5: ='3.1销售情况分析'!H33+'3.1销售情况分析'!H34 -> 0 | H5: ='3.1销售情况分析'!I33+'3.1销售情况分析'!I34 -> 0 | I5: ='3.1销售情况分析'!J33+'3.1销售情况分析'!J34 -> 0 | J5: ='3.1销售情况分析'!K33+'3.1销售情况分析'!K34 -> 0 | K5: ='3.1销售情况分析'!L33+'3.1销售情况分析'!L34 -> 0 | L5: ='3.1销售情况分析'!M33+'3.1销售情况分析'!M34 -> 0 | M5: ='3.1销售情况分析'!N33+'3.1销售情况分析'!N34 -> 0 | ... Y5: ='3.1销售情况分析'!Z33+'3.1销售情况分析'!Z34 -> 921.96832
B6: 3 | C6: 土增税 | E6: =SUM(F6:Y6) -> 0 | F6: ='3.1销售情况分析'!G52 -> 0 | G6: ='3.1销售情况分析'!H52 -> 0 | H6: ='3.1销售情况分析'!I52 -> 0 | I6: ='3.1销售情况分析'!J52 -> 0 | J6: ='3.1销售情况分析'!K52 -> 0 | K6: ='3.1销售情况分析'!L52 -> 0 | L6: ='3.1销售情况分析'!M52 -> 0 | M6: ='3.1销售情况分析'!N52 -> 0 | ... Y6: ='3.1销售情况分析'!Z52 -> 0
C43: 税金附加
C44: 实际缴纳与抵扣 | E44: =#REF!+#REF! -> #REF! | F44: =IF(E44=E45,"正确","错误") -> #REF!
C45: 销项税 | E45: =#REF! -> #REF!
C48: 可行性缺口补助（含增值税）
C49: 可用性服务费（扣除使用者付费部分）
C50: 运营绩效服务费（含增值税）
B52: 点击返回目录

Sheet 附表5 运营成本汇总表
A1: 附表5 运营成本费用汇总表 (单位：万元)
A2: 序号 | B2: 项目 | C2: 单位：万元 | D2: 合计 | E2: 第1年Q1 | F2: 第1年Q2 | G2: 第1年Q3 | H2: 第1年Q4 | I2: 第2年Q1 | J2: 第2年Q2 | K2: 第2年Q3 | L2: 第2年Q4 | M2: 第3年Q1 | N2: 第3年Q2 | O2: 第3年Q3 | P2: 第3年Q4 | Q2: 第4年Q1 | R2: 第4年Q2 | S2: 第4年Q3 | T2: 第4年Q4 | U2: 第5年Q1 | V2: 第5年Q2 | W2: 第5年Q3 | X2: 第5年Q4
A3: 1 | B3: 经营成本 | D3: =SUM(E3:X3) -> 7697.2536 | E3: ='5.1运营成本明细表'!G3 -> 0 | F3: ='5.1运营成本明细表'!H3 -> 100 | G3: ='5.1运营成本明细表'!I3 -> 100 | H3: ='5.1运营成本明细表'!J3 -> 1299.4507 | I3: ='5.1运营成本明细表'!K3 -> 567.28029 | J3: ='5.1运营成本明细表'!L3 -> 567.28029 | K3: ='5.1运营成本明细表'!M3 -> 747.1979 | L3: ='5.1运营成本明细表'!N3 -> 447.33522 | ... X3: ='5.1运营成本明细表'!Z3 -> 1406.8958
A9: 点击返回目录

Sheet 5.1运营成本明细表
A1: 附表5.1 运营成本测算表（万元）
A2: 序号 | B2: 项目 | C2: 单价 | D2: 数量 | E2: 备注 | F2: 合计 | G2: 第1年Q1 | H2: 第1年Q2 | I2: 第1年Q3 | J2: 第1年Q4 | K2: 第2年Q1 | L2: 第2年Q2 | M2: 第2年Q3 | N2: 第2年Q4 | O2: 第3年Q1 | P2: 第3年Q2 | Q2: 第3年Q3 | R2: 第3年Q4 | S2: 第4年Q1 | T2: 第4年Q2 | U2: 第4年Q3 | V2: 第4年Q4 | W2: 第5年Q1 | X2: 第5年Q2 | Y2: 第5年Q3 | Z2: 第5年Q4
B3: 合计 | F3: =SUM(G3:Z3) -> 7697.2536 | G3: =G4+G9 -> 0 | H3: =H4+H9 -> 100 | I3: =I4+I9 -> 100 | J3: =J4+J9 -> 1299.4507 | K3: =K4+K9 -> 567.28029 | L3: =L4+L9 -> 567.28029 | M3: =M4+M9 -> 747.1979 | N3: =N4+N9 -> 447.33522 | ... Z3: =Z4+Z9 -> 1406.8958
A4: 1 | B4: 经营维护成本 | F4: =SUM(G4:Z4) -> 5797.2536 | G4: =SUM(G5:G7) -> 0 | H4: =SUM(H5:H7) -> 0 | I4: =SUM(I5:I7) -> 0 | J4: =SUM(J5:J7) -> 1199.4507 | K4: =SUM(K5:K7) -> 467.28029 | L4: =SUM(L5:L7) -> 467.28029 | M4: =SUM(M5:M7) -> 647.1979 | N4: =SUM(N5:N7) -> 347.33522 | ... Z4: =SUM(Z5:Z7) -> 1306.8958
A5: 1.1 | B5: 销售费用 | F5: =SUM(G5:Z5) -> 4058.0775 | G5: =('3.1销售情况分析'!G79+'3.1销售情况分析'!G80+'3.1销售情况分析'!G81)*0.035 -> 0 | H5: =('3.1销售情况分析'!H79+'3.1销售情况分析'!H80+'3.1销售情况分析'!H81)*0.035 -> 0 | I5: =('3.1销售情况分析'!I79+'3.1销售情况分析'!I80+'3.1销售情况分析'!I81)*0.035 -> 0 | J5: =('3.1销售情况分析'!J79+'3.1销售情况分析'!J80+'3.1销售情况分析'!J81)*0.035 -> 839.6155 | K5: =('3.1销售情况分析'!K79+'3.1销售情况分析'!K80+'3.1销售情况分析'!K81)*0.035 -> 327.0962 | L5: =('3.1销售情况分析'!L79+'3.1销售情况分析'!L80+'3.1销售情况分析'!L81)*0.035 -> 327.0962 | M5: =('3.1销售情况分析'!M79+'3.1销售情况分析'!M80+'3.1销售情况分析'!M81)*0.035 -> 453.03853 | N5: =('3.1销售情况分析'!N79+'3.1销售情况分析'!N80+'3.1销售情况分析'!N81)*0.035 -> 243.13465 | ... Z5: =('3.1销售情况分析'!Z79+'3.1销售情况分析'!Z80+'3.1销售情况分析'!Z81)*0.035 -> 914.82705
A6: 1.2 | B6: 代建费用 | F6: =SUM(G6:Z6) -> 1739.1761 | G6: =('3.1销售情况分析'!G79+'3.1销售情况分析'!G80+'3.1销售情况分析'!G81)*0.015 -> 0 | H6: =('3.1销售情况分析'!H79+'3.1销售情况分析'!H80+'3.1销售情况分析'!H81)*0.015 -> 0 | I6: =('3.1销售情况分析'!I79+'3.1销售情况分析'!I80+'3.1销售情况分析'!I81)*0.015 -> 0 | J6: =('3.1销售情况分析'!J79+'3.1销售情况分析'!J80+'3.1销售情况分析'!J81)*0.015 -> 359.83522 | K6: =('3.1销售情况分析'!K79+'3.1销售情况分析'!K80+'3.1销售情况分析'!K81)*0.015 -> 140.18409 | L6: =('3.1销售情况分析'!L79+'3.1销售情况分析'!L80+'3.1销售情况分析'!L81)*0.015 -> 140.18409 | M6: =('3.1销售情况分析'!M79+'3.1销售情况分析'!M80+'3.1销售情况分析'!M81)*0.015 -> 194.15937 | N6: =('3.1销售情况分析'!N79+'3.1销售情况分析'!N80+'3.1销售情况分析'!N81)*0.015 -> 104.20056 | ... Z6: =('3.1销售情况分析'!Z79+'3.1销售情况分析'!Z80+'3.1销售情况分析'!Z81)*0.015 -> 392.06874
A7: 1.3 | B7: 大修费
A9: 2 | B9: 项目公司成本 | F9: =SUM(G9:Z9) -> 1900 | G9: =SUM(G10:G12) -> 0 | H9: =SUM(H10:H12) -> 100 | I9: =SUM(I10:I12) -> 100 | J9: =SUM(J10:J12) -> 100 | K9: =SUM(K10:K12) -> 100 | L9: =SUM(L10:L12) -> 100 | M9: =SUM(M10:M12) -> 100 | N9: =SUM(N10:N12) -> 100 | ... Z9: =SUM(Z10:Z12) -> 100
A10: 2.1 | B10: 工资福利 | F10: =SUM(G10:Z10) -> 1900 | H10: 100 | I10: 100 | J10: 100 | K10: 100 | L10: 100 | M10: 100 | N10: 100 | O10: 100 | P10: 100 | Q10: 100 | R10: 100 | S10: 100 | T10: 100 | U10: 100 | V10: 100 | W10: 100 | X10: 100 | Y10: 100 | Z10: 100
A11: 2.2 | B11: 其他费用支出 | F11: =SUM(G11:Z11) -> 0
A12: 2.3
B14: 经营成本引用数据 | C14: 参数-百万$ | D14: 年增长率 | E14: 备注
B15: 运营养护费用（百万元/年） | C15: ='0基本假设 '!L76 -> 0 | D15: 0.03 | E15: 0.02
B16: 运营管理费用（百万元/年） | C16: ='0基本假设 '!L77 -> 0 | D16: 0.03 | E16: 0.02
B17: 大修费用（倍数*当年养护费用） | C17: ='0基本假设 '!L78 -> 0 | D17: 0.02 | E17: 每10年1次
A19: 点击返回目录

Sheet 附表6 资产折旧摊销表
B2: 附表6 资产折旧与摊销表 (单位：万元)
B3: 序号 | C3: 项目 | D3: 合计 | E3: 第1年Q1 | F3: 第1年Q2 | G3: 第1年Q3 | H3: 第1年Q4 | I3: 第2年Q1 | J3: 第2年Q2 | K3: 第2年Q3 | L3: 第2年Q4 | M3: 第3年Q1 | N3: 第3年Q2 | O3: 第3年Q3 | P3: 第3年Q4 | Q3: 第4年Q1 | R3: 第4年Q2 | S3: 第4年Q3 | T3: 第4年Q4 | U3: 第5年Q1 | V3: 第5年Q2 | W3: 第5年Q3 | X3: 第5年Q4
B4: 1 | C4: 初始投资
B5: 1.1 | C5: 建设投资（当期在建工程） | D5: =SUM(E5:U5) -> 106762.97 | E5: ='附表2 投资计划与资金筹措平衡表 '!D5-'附表2 投资计划与资金筹措平衡表 '!D21 -> 59832.185 | F5: ='附表2 投资计划与资金筹措平衡表 '!E5-'附表2 投资计划与资金筹措平衡表 '!E21 -> 8809.0863 | G5: ='附表2 投资计划与资金筹措平衡表 '!F5-'附表2 投资计划与资金筹措平衡表 '!F21 -> 4535.6958 | H5: ='附表2 投资计划与资金筹措平衡表 '!G5-'附表2 投资计划与资金筹措平衡表 '!G21 -> 4601.2721 | I5: ='附表2 投资计划与资金筹措平衡表 '!H5-'附表2 投资计划与资金筹措平衡表 '!H21 -> 4666.8485 | J5: ='附表2 投资计划与资金筹措平衡表 '!I5-'附表2 投资计划与资金筹措平衡表 '!I21 -> 4732.4248 | K5: ='附表2 投资计划与资金筹措平衡表 '!J5-'附表2 投资计划与资金筹措平衡表 '!J21 -> 4798.0011 | L5: ='附表2 投资计划与资金筹措平衡表 '!K5-'附表2 投资计划与资金筹措平衡表 '!K21 -> 4863.5774 | ... N5: ='附表2 投资计划与资金筹措平衡表 '!M5-'附表2 投资计划与资金筹措平衡表 '!M21 -> 4994.7301
B6: 1.1.1 | C6: 原值 | H6: =SUM($E$5:H5) -> 77778.239 | I6: =SUM($E$5:I5) -> 82445.088 | J6: =SUM($E$5:J5) -> 87177.513 | K6: =SUM($E$5:K5) -> 91975.514 | L6: =SUM($E$5:L5) -> 96839.091 | M6: =SUM($E$5:M5) -> 101768.24 | N6: =SUM($E$5:N5) -> 106762.97 | O6: =SUM($E$5:O5) -> 106762.97 | ... X6: =SUM($E$5:X5) -> 106762.97
B7: 1.1.2 | C7: 当期摊销费 | D7: =SUM(E7:X7) -> 106762.97 | E7: =$D$5*'3.2 营业收入汇总表'!D11 -> 0 | F7: =$D$5*'3.2 营业收入汇总表'!E11 -> 0 | G7: =$D$5*'3.2 营业收入汇总表'!F11 -> 0 | H7: =$D$5*'3.2 营业收入汇总表'!G11 -> 25292.129 | I7: =$D$5*'3.2 营业收入汇总表'!H11 -> 10740.754 | J7: =$D$5*'3.2 营业收入汇总表'!I11 -> 10740.754 | K7: =$D$5*'3.2 营业收入汇总表'!J11 -> 14054.14 | L7: =$D$5*'3.2 营业收入汇总表'!K11 -> 8531.8299 | ... X7: =$D$5*'3.2 营业收入汇总表'!W11 -> 22466.518
B8: 1.1.3 | C8: 净值 | H8: =SUM($E$5:H5)-SUM($E$7:H7) -> 52486.11 | I8: =SUM($E$5:I5)-SUM($E$7:I7) -> 46412.204 | J8: =SUM($E$5:J5)-SUM($E$7:J7) -> 40403.875 | K8: =SUM($E$5:K5)-SUM($E$7:K7) -> 31147.736 | L8: =SUM($E$5:L5)-SUM($E$7:L7) -> 27479.484 | M8: =SUM($E$5:M5)-SUM($E$7:M7) -> 26085.732 | N8: =SUM($E$5:N5)-SUM($E$7:N7) -> 25862.018 | O8: =SUM($E$5:O5)-SUM($E$7:O7) -> 25484.74 | ... X8: =SUM($E$5:X5)-SUM($E$7:X7) -> 0
B9: 1.2 | C9: 设备（当期在建工程）
B10: 1.2.1 | C10: 原值
B11: 1.2.2 | C11: 当期摊销费
B12: 1.2.3 | C12: 净值 | D12: =SUM(E12:X12) -> 0
B13: 1.3 | C13: 初始投资小计（当期固定资产） | D13: =SUM(E13:X13) -> 106762.97 | E13: =E5 -> 59832.185 | F13: =F5 -> 8809.0863 | G13: =G5 -> 4535.6958 | H13: =H5 -> 4601.2721 | I13: =I5 -> 4666.8485 | J13: =J5 -> 4732.4248 | K13: =K5 -> 4798.0011 | L13: =L5 -> 4863.5774 | ... N13: =N5 -> 4994.7301
B14: 1.3.1 | C14: 原值 | E14: =E6 -> 0 | F14: =F6 -> 0 | G14: =G6 -> 0 | H14: =H6 -> 77778.239 | I14: =I6 -> 82445.088 | J14: =J6 -> 87177.513 | K14: =K6 -> 91975.514 | L14: =L6 -> 96839.091 | ... Q14: =Q6 -> 106762.97 | R14: =R6+R10 -> 106762.97 | S14: =S6+S10 -> 106762.97 | T14: =T6 -> 106762.97 | U14: =U6 -> 106762.97 | V14: =V6 -> 106762.97 | W14: =W6 -> 106762.97 | X14: =X6 -> 106762.97
B15: 1.3.2 | C15: 当期摊销费 | D15: =SUM(E15:X15) -> 106762.97 | H15: =H7+H11 -> 25292.129 | I15: =I7+I11 -> 10740.754 | J15: =J7+J11 -> 10740.754 | K15: =K7+K11 -> 14054.14 | L15: =L7+L11 -> 8531.8299 | M15: =M7+M11 -> 6322.9059 | N15: =N7+N11 -> 5218.4439 | O15: =O7+O11 -> 377.27777 | ... X15: =X7+X11 -> 22466.518
B16: 1.3.3 | C16: 净值 | E16: =E8+E12 -> 0 | F16: =F8+F12 -> 0 | G16: =G8+G12 -> 0 | H16: =H8+H12 -> 52486.11 | I16: =I8+I12 -> 46412.204 | J16: =J8+J12 -> 40403.875 | K16: =K8+K12 -> 31147.736 | L16: =L8+L12 -> 27479.484 | ... X16: =X8+X12 -> 0
B18: 点击返回目录

Sheet 附表7 银行贷款还本付息表
B2: 附表7银行贷款还本付息表 (单位：万元)
B3: 序号 | C3: 项目 | D3: 合 计 | E3: 建设期 | O3: 赛事期 | P3: 运营期
E4: 第1年Q1 | F4: 第1年Q2 | G4: 第1年Q3 | H4: 第1年Q4 | I4: 第2年Q1 | J4: 第2年Q2 | K4: 第2年Q3 | L4: 第2年Q4 | M4: 第3年Q1 | N4: 第3年Q2 | O4: 第3年Q3 | P4: 第3年Q4 | Q4: 第4年Q1 | R4: 第4年Q2 | S4: 第4年Q3 | T4: 第4年Q4 | U4: 第5年Q1 | V4: 第5年Q2 | W4: 第5年Q3 | X4: 第5年Q4
B5: 清水湾项目
B6: 1.1 | C6: 期初借款累计 | E6: 0 | F6: =E14 -> 0 | G6: =F14 -> 8743.51 | H6: =G14 -> 13115.265 | I6: =H14 -> 17487.02 | J6: =I14 -> 21858.775 | K6: =J14 -> 26230.53 | L6: =K14 -> 30602.285 | M6: =L14 -> 34974.04 | ... X6: =W14 -> 4670.4203
B7: 1.2 | C7: 当期借款 | D7: =SUM(E7:X7) -> 43717.55 | E7: ='附表2 投资计划与资金筹措平衡表 '!D16 -> 0 | F7: ='附表2 投资计划与资金筹措平衡表 '!E16 -> 8743.51 | G7: ='附表2 投资计划与资金筹措平衡表 '!F16 -> 4371.755 | H7: ='附表2 投资计划与资金筹措平衡表 '!G16 -> 4371.755 | I7: ='附表2 投资计划与资金筹措平衡表 '!H16 -> 4371.755 | J7: ='附表2 投资计划与资金筹措平衡表 '!I16 -> 4371.755 | K7: ='附表2 投资计划与资金筹措平衡表 '!J16 -> 4371.755 | L7: ='附表2 投资计划与资金筹措平衡表 '!K16 -> 4371.755 | ... O7: ='附表2 投资计划与资金筹措平衡表 '!N16 -> 0 | P7: 0 | Q7: 0 | R7: 0 | S7: 0 | T7: 0 | U7: 0 | V7: 0 | W7: 0 | X7: 0
B8: 1.3 | C8: 当期应计建设期利息 | D8: =SUM(E8:X8) -> 3213.2399 | E8: ='附表2 投资计划与资金筹措平衡表 '!D9 -> 0 | F8: ='附表2 投资计划与资金筹措平衡表 '!E9 -> 65.576325 | G8: ='附表2 投资计划与资金筹措平衡表 '!F9 -> 163.94081 | H8: ='附表2 投资计划与资金筹措平衡表 '!G9 -> 229.51714 | I8: ='附表2 投资计划与资金筹措平衡表 '!H9 -> 295.09346 | J8: ='附表2 投资计划与资金筹措平衡表 '!I9 -> 360.66979 | K8: ='附表2 投资计划与资金筹措平衡表 '!J9 -> 426.24611 | L8: ='附表2 投资计划与资金筹措平衡表 '!K9 -> 491.82244 | ... N8: ='附表2 投资计划与资金筹措平衡表 '!M9 -> 622.97509
B9: 1.4 | C9: 当期应计运营期利息 | D9: =SUM(E9:X9) -> 3687.2159 | O9: =O6*'0基本假设 '!$L$34 -> 655.76325 | P9: =P6*'0基本假设 '!$L$34 -> 594.49255 | Q9: =Q6*'0基本假设 '!$L$34 -> 532.30279 | R9: =R6*'0基本假设 '!$L$34 -> 469.18018 | S9: =S6*'0基本假设 '!$L$34 -> 405.11074 | T9: =T6*'0基本假设 '!$L$34 -> 340.08025 | U9: =U6*'0基本假设 '!$L$34 -> 274.0743 | V9: =V6*'0基本假设 '!$L$34 -> 207.07827 | ... X9: =X6*'0基本假设 '!$L$34 -> 70.056304
B10: 1.5 | C10: 当期还本付息 | D10: =SUM(E10:X10) -> 50618.006 | E10: =SUM(E11:E13) -> 0 | F10: =SUM(F11:F13) -> 65.576325 | G10: =SUM(G11:G13) -> 163.94081 | H10: =SUM(H11:H13) -> 229.51714 | I10: =SUM(I11:I13) -> 295.09346 | J10: =SUM(J11:J13) -> 360.66979 | K10: =SUM(K11:K13) -> 426.24611 | L10: =SUM(L11:L13) -> 491.82244 | ... N10: =SUM(N11:N13) -> 622.97509 | O10: =-PMT('0基本假设 '!$L$34,'0基本假设 '!$L$28,'附表7 银行贷款还本付息表'!$O$6) -> 4740.4766 | P10: =-PMT('0基本假设 '!$L$34,'0基本假设 '!$L$28,'附表7 银行贷款还本付息表'!$O$6) -> 4740.4766 | Q10: =-PMT('0基本假设 '!$L$34,'0基本假设 '!$L$28,'附表7 银行贷款还本付息表'!$O$6) -> 4740.4766 | R10: =-PMT('0基本假设 '!$L$34,'0基本假设 '!$L$28,'附表7 银行贷款还本付息表'!$O$6) -> 4740.4766 | S10: =-PMT('0基本假设 '!$L$34,'0基本假设 '!$L$28,'附表7 银行贷款还本付息表'!$O$6) -> 4740.4766 | T10: =-PMT('0基本假设 '!$L$34,'0基本假设 '!$L$28,'附表7 银行贷款还本付息表'!$O$6) -> 4740.4766 | U10: =-PMT('0基本假设 '!$L$34,'0基本假设 '!$L$28,'附表7 银行贷款还本付息表'!$O$6) -> 4740.4766 | V10: =-PMT('0基本假设 '!$L$34,'0基本假设 '!$L$28,'附表7 银行贷款还本付息表'!$O$6) -> 4740.4766 | ... X10: =-PMT('0基本假设 '!$L$34,'0基本假设 '!$L$28,'附表7 银行贷款还本付息表'!$O$6) -> 4740.4766
B11: 1.5.1 | C11: 其中：还本 | D11: =SUM(E11:X11) -> 43717.55 | O11: =O10-O13 -> 4084.7133 | P11: =P10-P13 -> 4145.984 | Q11: =Q10-Q13 -> 4208.1738 | R11: =R10-R13 -> 4271.2964 | S11: =S10-S13 -> 4335.3659 | T11: =T10-T13 -> 4400.3963 | U11: =U10-U13 -> 4466.4023 | V11: =V10-V13 -> 4533.3983 | ... X11: =X10-X13 -> 4670.4203
B12: 1.5.2 | C12: 支付建设期利息 | D12: =SUM(E12:X12) -> 3213.2399 | E12: =E8 -> 0 | F12: =F8 -> 65.576325 | G12: =G8 -> 163.94081 | H12: =H8 -> 229.51714 | I12: =I8 -> 295.09346 | J12: =J8 -> 360.66979 | K12: =K8 -> 426.24611 | L12: =L8 -> 491.82244 | ... N12: =N8 -> 622.97509
B13: 1.5.3 | C13: 支付运营期利息 | D13: =SUM(E13:X13) -> 3687.2159 | O13: =O6*'0基本假设 '!$L$34 -> 655.76325 | P13: =P6*'0基本假设 '!$L$34 -> 594.49255 | Q13: =Q6*'0基本假设 '!$L$34 -> 532.30279 | R13: =R6*'0基本假设 '!$L$34 -> 469.18018 | S13: =S6*'0基本假设 '!$L$34 -> 405.11074 | T13: =T6*'0基本假设 '!$L$34 -> 340.08025 | U13: =U6*'0基本假设 '!$L$34 -> 274.0743 | V13: =V6*'0基本假设 '!$L$34 -> 207.07827 | ... X13: =X6*'0基本假设 '!$L$34 -> 70.056304
B14: 2 | C14: 期末借款余额 | E14: =E6+E7-E11 -> 0 | F14: =F6+F7-F11 -> 8743.51 | G14: =G6+G7-G11 -> 13115.265 | H14: =H6+H7-H11 -> 17487.02 | I14: =I6+I7-I11 -> 21858.775 | J14: =J6+J7-J11 -> 26230.53 | K14: =K6+K7-K11 -> 30602.285 | L14: =L6+L7-L11 -> 34974.04 | ... X14: =X6+X7-X11 -> 0
B18: 合计
B19: 1.1 | C19: 期初借款累计 | D19: =D6 -> 0 | E19: =E6 -> 0 | F19: =F6 -> 0 | G19: =G6 -> 8743.51 | H19: =H6 -> 13115.265 | I19: =I6 -> 17487.02 | J19: =J6 -> 21858.775 | K19: =K6 -> 26230.53 | ... X19: =X6 -> 4670.4203
B20: 1.2 | C20: 当期借款 | D20: =D7 -> 43717.55 | E20: =E7 -> 0 | F20: =F7 -> 8743.51 | G20: =G7 -> 4371.755 | H20: =H7 -> 4371.755 | I20: =I7 -> 4371.755 | J20: =J7 -> 4371.755 | K20: =K7 -> 4371.755 | ... X20: =X7 -> 0
B21: 1.3 | C21: 当期应计建设期利息 | D21: =D8 -> 3213.2399 | E21: =E8 -> 0 | F21: =F8 -> 65.576325 | G21: =G8 -> 163.94081 | H21: =H8 -> 229.51714 | I21: =I8 -> 295.09346 | J21: =J8 -> 360.66979 | K21: =K8 -> 426.24611 | ... X21: =X8 -> 0
B22: 1.4 | C22: 当期应计运营期利息 | D22: =D9 -> 3687.2159 | E22: =E9 -> 0 | F22: =F9 -> 0 | G22: =G9 -> 0 | H22: =H9 -> 0 | I22: =I9 -> 0 | J22: =J9 -> 0 | K22: =K9 -> 0 | ... X22: =X9 -> 70.056304
B23: 1.5 | C23: 当期还本付息 | D23: =D10 -> 50618.006 | E23: =E10 -> 0 | F23: =F10 -> 65.576325 | G23: =G10 -> 163.94081 | H23: =H10 -> 229.51714 | I23: =I10 -> 295.09346 | J23: =J10 -> 360.66979 | K23: =K10 -> 426.24611 | ... X23: =X10 -> 4740.4766
B24: 1.5.1 | C24: 其中：还本 | D24: =D11 -> 43717.55 | E24: =E11 -> 0 | F24: =F11 -> 0 | G24: =G11 -> 0 | H24: =H11 -> 0 | I24: =I11 -> 0 | J24: =J11 -> 0 | K24: =K11 -> 0 | ... X24: =X11 -> 4670.4203
B25: 1.5.2 | C25: 支付建设期利息 | D25: =D12 -> 3213.2399 | E25: =E12 -> 0 | F25: =F12 -> 65.576325 | G25: =G12 -> 163.94081 | H25: =H12 -> 229.51714 | I25: =I12 -> 295.09346 | J25: =J12 -> 360.66979 | K25: =K12 -> 426.24611 | ... X25: =X12 -> 0
B26: 1.5.3 | C26: 支付运营期利息 | D26: =D13 -> 3687.2159 | E26: =E13 -> 0 | F26: =F13 -> 0 | G26: =G13 -> 0 | H26: =H13 -> 0 | I26: =I13 -> 0 | J26: =J13 -> 0 | K26: =K13 -> 0 | ... X26: =X13 -> 70.056304
B27: 2 | C27: 期末借款余额 | D27: =D14 -> 0 | E27: =E14 -> 0 | F27: =F14 -> 8743.51 | G27: =G14 -> 13115.265 | H27: =H14 -> 17487.02 | I27: =I14 -> 21858.775 | J27: =J14 -> 26230.53 | K27: =K14 -> 30602.285 | ... X27: =X14 -> 0
C29: 提前还本 | O29: ='附表11 财务计划现金流量表'!O34 -> -19622.722 | P29: ='附表11 财务计划现金流量表'!P34 -> 474.24638 | Q29: ='附表11 财务计划现金流量表'!Q34 -> 480.46535 | R29: ='附表11 财务计划现金流量表'!R34 -> 486.77761 | T29: ='附表11 财务计划现金流量表'!#REF! -> #REF! | U29: ='附表11 财务计划现金流量表'!#REF! -> #REF!
C31: 偿债备付率EBITDA/ | D31: =附表9利润表!C50/'附表7 银行贷款还本付息表'!D23 -> 2.1203097 | I31: =附表9利润表!I50/'附表7 银行贷款还本付息表'!I23 -> 29.747611 | J31: =附表9利润表!J50/'附表7 银行贷款还本付息表'!J23 -> 33.816972 | K31: =附表9利润表!K50/'附表7 银行贷款还本付息表'!K23 -> 15.247926 | L31: =附表9利润表!L50/'附表7 银行贷款还本付息表'!L23 -> 8.5811716 | M31: =附表9利润表!M50/'附表7 银行贷款还本付息表'!M23 -> 5.5273437 | N31: =附表9利润表!M50/'附表7 银行贷款还本付息表'!N23 -> 4.9455181 | O31: =附表9利润表!N50/'附表7 银行贷款还本付息表'!O23 -> 0.40954877 | P31: =附表9利润表!O50/'附表7 银行贷款还本付息表'!P23 -> 0.40954877 | Q31: =附表9利润表!P50/'附表7 银行贷款还本付息表'!Q23 -> 0.40954877 | R31: =附表9利润表!Q50/'附表7 银行贷款还本付息表'!R23 -> 0.40954877 | S31: =附表9利润表!R50/'附表7 银行贷款还本付息表'!S23 -> 0.40954877 | T31: =附表9利润表!S50/'附表7 银行贷款还本付息表'!T23 -> 0.40954877 | U31: =附表9利润表!T50/'附表7 银行贷款还本付息表'!U23 -> 0.40954877 | ... X31: =附表9利润表!W50/'附表7 银行贷款还本付息表'!X23 -> 5.0225017
C32: 利息备付率 | D32: =附表9利润表!C19/D26 -> 0.15265587 | E32: =附表9利润表!D19/E26 -> #DIV/0! | F32: =附表9利润表!E19/F26 -> #DIV/0! | G32: =附表9利润表!F19/G26 -> #DIV/0! | H32: =附表9利润表!G19/H26 -> #DIV/0! | I32: =附表9利润表!H19/I26 -> #DIV/0! | J32: =附表9利润表!I19/J26 -> #DIV/0! | K32: =附表9利润表!J19/K26 -> #DIV/0! | ... X32: =附表9利润表!W19/X26 -> 19.16364
B34: 点击返回目录

Sheet 附表8 总成本估算表
B1: 附表8.1 总成本估算表（含税）(单位：万元)
B2: 序号 | C2: 项目 | D2: 合计 | E2: 第1年Q1 | F2: 第1年Q2 | G2: 第1年Q3 | H2: 第1年Q4 | I2: 第2年Q1 | J2: 第2年Q2 | K2: 第2年Q3 | L2: 第2年Q4 | M2: 第3年Q1 | N2: 第3年Q2 | O2: 第3年Q3 | P2: 第3年Q4 | Q2: 第4年Q1 | R2: 第4年Q2 | S2: 第4年Q3 | T2: 第4年Q4 | U2: 第5年Q1 | V2: 第5年Q2 | W2: 第5年Q3 | X2: 第5年Q4
